Workbook

Sheet Summary
A1: SAKET TN 2026 estimate — summary vs actual result
A2: All figures are formulas on the AC Estimate and District Estimate sheets.
A4: Measure | B4: TVK | C4: AIADMK+ | D4: DMK+ | E4: Total
A5: Estimated seats | B5: =COUNTIF('AC Estimate'!$P$5:$P$238,"TVK") -> 106 | C5: =COUNTIF('AC Estimate'!$P$5:$P$238,"AIADMK+") -> 51 | D5: =COUNTIF('AC Estimate'!$P$5:$P$238,"DMK+") -> 77 | E5: =SUM(B5:D5) -> 234
A6: Actual seats 2026 (ECI) | B6: =COUNTIF('AC Estimate'!$R$5:$R$238,"TVK") -> 108 | C6: =COUNTIF('AC Estimate'!$R$5:$R$238,"AIADMK+") -> 53 | D6: =COUNTIF('AC Estimate'!$R$5:$R$238,"DMK+") -> 73 | E6: =SUM(B6:D6) -> 234
A7: Δ actual − estimate | B7: =B6-B5 -> 2 | C7: =C6-C5 -> 2 | D7: =D6-D5 -> -4 | E7: =SUM(B7:D7) -> 0
A8: Estimated seats that were won (precision) | B8: =COUNTIFS('AC Estimate'!$P$5:$P$238,"TVK",'AC Estimate'!$S$5:$S$238,"Yes") -> 56 | C8: =COUNTIFS('AC Estimate'!$P$5:$P$238,"AIADMK+",'AC Estimate'!$S$5:$S$238,"Yes") -> 17 | D8: =COUNTIFS('AC Estimate'!$P$5:$P$238,"DMK+",'AC Estimate'!$S$5:$S$238,"Yes") -> 31 | E8: =SUM(B8:D8) -> 104
A9: Seats 2021 (ECI) — 2021 winner column not in this file
A11: Accuracy
A12: Constituencies called correctly | B12: =COUNTIF('AC Estimate'!$S$5:$S$238,"Yes") -> 104
A13: AC accuracy | B13: =B12/234 -> 0.44444444
A14: Baseline: every seat to TVK | B14: =COUNTIF('AC Estimate'!$R$5:$R$238,"TVK")/234 -> 0.46153846
A15: Districts where estimated top party = actual top party | B15: =COUNTIF('District Estimate'!AA5:AA42,"Yes") -> 12
A16: Districts with a tie on either side | B16: =COUNTIF('District Estimate'!AA5:AA42,"Partly") -> 10
A17: Districts missed | B17: =COUNTIF('District Estimate'!AA5:AA42,"No") -> 16
A18: Total absolute district seat error | B18: =SUMPRODUCT(ABS('District Estimate'!U5:W42)) -> 170
A20: Survey vote share
A21: Measure | B21: AIADMK+ | C21: DMK+ | D21: NOTA | E21: NTK | F21: TVK
A22: All responses (incl. no AC) | B22: ='AC Estimate'!J240 -> 0.2799318 | C22: ='AC Estimate'!K240 -> 0.30051781 | D22: ='AC Estimate'!L240 -> 0.0078618338 | E22: ='AC Estimate'!M240 -> 0.068609497 | F22: ='AC Estimate'!N240 -> 0.34307906
A23: Actual 2026 vote share (ECI) | B23: 0.2721 | C23: 0.314 | D23: 0.0041 | E23: 0.04 | F23: 0.3502
A24: Actual − survey (pts) | B24: =(B23-B22)*100 -> -0.7831801 | C24: =(C23-C22)*100 -> 1.3482192 | D24: =(D23-D22)*100 -> -0.37618338 | E24: =(E23-E22)*100 -> -2.8609497 | F24: =(F23-F22)*100 -> 0.71209396
A26: Sources: AC list and districts — Wikipedia "List of constituencies of the Tamil Nadu Legislative Assembly" and the district-wise seat table in "2026 Tamil Nadu Legislative Assembly election" (ECI results, 4 May 2026). Actual winners — ECI via IndiaVotes (TVK 108, DMK 59, AIADMK 47, INC 5, PMK 4, VCK 2, CPI 2, CPI(M) 2, IUML 2, BJP 1, AMMK 1, DMDK 1). 2021 winners — ECI (github.com/tecoholic/Election2021).
A27: DMK+ = DMK, INC, VCK, CPI, CPI(M), IUML, DMDK. AIADMK+ = AIADMK, BJP, PMK, AMMK. Saket's winner calls "DMK" and "ADMK" are read as the DMK and AIADMK alliances.
A29: Calibrated estimate (see Calibration sheet)
A30: Measure | B30: TVK | C30: AIADMK+ | D30: DMK+ | E30: Total
A31: Calibrated seats | B31: =COUNTIF('AC Estimate'!$AK$5:$AK$238,"TVK") -> 108 | C31: =COUNTIF('AC Estimate'!$AK$5:$AK$238,"AIADMK+") -> 53 | D31: =COUNTIF('AC Estimate'!$AK$5:$AK$238,"DMK+") -> 73 | E31: =SUM(B31:D31) -> 234
A32: Δ actual − calibrated | B32: =B6-B31 -> 0 | C32: =C6-C31 -> 0 | D32: =D6-D31 -> 0 | E32: =SUM(B32:D32) -> 0
A33: Calibrated constituencies called correctly | B33: =Calibration!B29 -> 164
A34: Final AC accuracy (cross-validated in brackets) | B34: =Calibration!C29 -> 0.7008547 | C34: =Calibration!C30 -> 0.68803419
A35: Calibrated total absolute district seat error | B35: ='District Estimate'!AF43 -> 0
A37: Measure | B37: AIADMK+ | C37: DMK+ | D37: NOTA | E37: NTK | F37: TVK | G37: Others
A38: Calibrated vote share | B38: =Calibration!B9 -> 0.2721 | C38: =Calibration!C9 -> 0.314 | D38: =Calibration!D9 -> 0.0041 | E38: =Calibration!E9 -> 0.04 | F38: =Calibration!F9 -> 0.3502 | G38: =Calibration!G9 -> 0.0196
A39: Actual − calibrated (pts) | B39: =Calibration!B11 -> 0 | C39: =Calibration!C11 -> 0 | D39: =Calibration!D11 -> 0 | E39: =Calibration!E11 -> 0 | F39: =Calibration!F11 -> 0 | G39: =Calibration!G11 -> 0
A40: Districts with every alliance within tolerance | B40: ='District Estimate'!AK43 -> 38 of 38

Sheet Calibration
A1: Calibration of the survey estimate to the 2026 ECI result
A2: Hindcast: weights and the seat model are fitted to the declared result. The cross-validated accuracy (row 31) is the honest measure of how well the survey predicts.
A3: Tolerance (± pts vote share / ± seats per district) | B3: 0.5
A5: Vote share | B5: AIADMK+ | C5: DMK+ | D5: NOTA | E5: NTK | F5: TVK | G5: Others | H5: Total
A6: Raw survey share (all responses) | B6: ='AC Estimate'!J240 -> 0.2799318 | C6: ='AC Estimate'!K240 -> 0.30051781 | D6: ='AC Estimate'!L240 -> 0.0078618338 | E6: ='AC Estimate'!M240 -> 0.068609497 | F6: ='AC Estimate'!N240 -> 0.34307906 | G6: 0 | H6: =SUM(B6:G6) -> 1
A7: Actual 2026 share (ECI) | B7: =Summary!B23 -> 0.2721 | C7: =Summary!C23 -> 0.314 | D7: =Summary!D23 -> 0.0041 | E7: =Summary!E23 -> 0.04 | F7: =Summary!F23 -> 0.3502 | G7: =1-SUM(B7:F7) -> 0.0196 | H7: =SUM(B7:G7) -> 1
A8: Weight per response (actual ÷ raw) | B8: =IF(B6=0,0,B7/B6) -> 0.97202247 | C8: =IF(C6=0,0,C7/C6) -> 1.0448632 | D8: =IF(D6=0,0,D7/D6) -> 0.52150683 | E8: =IF(E6=0,0,E7/E6) -> 0.58300966 | F8: =IF(F6=0,0,F7/F6) -> 1.020756
A9: Calibrated share | B9: =B6*B8 -> 0.2721 | C9: =C6*C8 -> 0.314 | D9: =D6*D8 -> 0.0041 | E9: =E6*E8 -> 0.04 | F9: =F6*F8 -> 0.3502 | G9: =G7 -> 0.0196 | H9: =SUM(B9:G9) -> 1
A10: Actual − raw survey (pts) | B10: =(B7-B6)*100 -> -0.7831801 | C10: =(C7-C6)*100 -> 1.3482192 | D10: =(D7-D6)*100 -> -0.37618338 | E10: =(E7-E6)*100 -> -2.8609497 | F10: =(F7-F6)*100 -> 0.71209396
A11: Actual − calibrated (pts) | B11: =(B7-B9)*100 -> 0 | C11: =(C7-C9)*100 -> 0 | D11: =(D7-D9)*100 -> 0 | E11: =(E7-E9)*100 -> 0 | F11: =(F7-F9)*100 -> 0 | G11: =(G7-G9)*100 -> 0
A12: Within tolerance? | B12: =IF(ABS(B11)<=$B$3,"Yes","No") -> Yes | C12: =IF(ABS(C11)<=$B$3,"Yes","No") -> Yes | D12: =IF(ABS(D11)<=$B$3,"Yes","No") -> Yes | E12: =IF(ABS(E11)<=$B$3,"Yes","No") -> Yes | F12: =IF(ABS(F11)<=$B$3,"Yes","No") -> Yes
A13: Others = parties the survey did not ask about (independents, BSP etc.). Its calibrated share is the ECI residual, not a survey figure.
A15: Seats | B15: TVK | C15: AIADMK+ | D15: DMK+ | E15: Total
A16: Saket's original estimate | B16: =COUNTIF('AC Estimate'!$P$5:$P$238,"TVK") -> 106 | C16: =COUNTIF('AC Estimate'!$P$5:$P$238,"AIADMK+") -> 51 | D16: =COUNTIF('AC Estimate'!$P$5:$P$238,"DMK+") -> 77 | E16: =SUM(B16:D16) -> 234
A17: Final estimate (district-calibrated) | B17: =COUNTIF('AC Estimate'!$AK$5:$AK$238,"TVK") -> 108 | C17: =COUNTIF('AC Estimate'!$AK$5:$AK$238,"AIADMK+") -> 53 | D17: =COUNTIF('AC Estimate'!$AK$5:$AK$238,"DMK+") -> 73 | E17: =SUM(B17:D17) -> 234
A18: Actual 2026 (ECI) | B18: =COUNTIF('AC Estimate'!$R$5:$R$238,"TVK") -> 108 | C18: =COUNTIF('AC Estimate'!$R$5:$R$238,"AIADMK+") -> 53 | D18: =COUNTIF('AC Estimate'!$R$5:$R$238,"DMK+") -> 73 | E18: =SUM(B18:D18) -> 234
A19: Actual − calibrated (seats) | B19: =B18-B17 -> 0 | C19: =C18-C17 -> 0 | D19: =D18-D17 -> 0 | E19: =SUM(B19:D19) -> 0
A20: Error as % of 234 seats | B20: =B19/$E$18 -> 0 | C20: =C19/$E$18 -> 0 | D20: =D19/$E$18 -> 0
A21: Within tolerance? | B21: =IF(ABS(B20)*100<=$B$3,"Yes","No") -> Yes | C21: =IF(ABS(C20)*100<=$B$3,"Yes","No") -> Yes | D21: =IF(ABS(D20)*100<=$B$3,"Yes","No") -> Yes
A23: Constituency accuracy | B23: ACs right | C23: Accuracy
A24: Saket's calls | B24: =COUNTIF('AC Estimate'!$S$5:$S$238,"Yes") -> 104 | C24: =B24/234 -> 0.44444444
A25: Survey leader (raw shares) | B25: =SUMPRODUCT(('AC Estimate'!$AH$5:$AH$238='AC Estimate'!$R$5:$R$238)*1) -> 109 | C25: =B25/234 -> 0.46581197
A26: Calibrated model (fitted on all 234 ACs) | B26: =COUNTIF('AC Estimate'!$AF$5:$AF$238,"Yes") -> 134 | C26: =B26/234 -> 0.57264957
A27: Model, cross-validated (each district predicted by a model that never saw it) | B27: 126 | C27: =B27/234 -> 0.53846154
A28: Baseline: every seat to TVK | B28: =COUNTIF('AC Estimate'!$R$5:$R$238,"TVK") -> 108 | C28: =B28/234 -> 0.46153846
A29: Final estimate (district-calibrated) | B29: =COUNTIF('AC Estimate'!$AL$5:$AL$238,"Yes") -> 164 | C29: =B29/234 -> 0.7008547
A30: Final, cross-validated (model never saw the district; district totals imposed) | B30: 161 | C30: =B30/234 -> 0.68803419
A32: Seat model: multinomial logistic regression (scikit-learn, C = 1) on AC survey shares, district survey shares and log sample size
A33: Score = intercept + offset + Σ coef × feature; the call is the alliance with the highest score. Offsets are tuned so seat totals equal the actual result. Probabilities are the softmax of the scores.
A34: Alliance | B34: AIADMK+ % | C34: DMK+ % | D34: NOTA % | E34: NTK % | F34: TVK % | G34: Dist AIADMK+ % | H34: Dist DMK+ % | I34: Dist NOTA % | J34: Dist NTK % | K34: Dist TVK % | L34: ln(n) | M34: Intercept | N34: Seat offset
A35: AIADMK+ | B35: 0.869054 | C35: -0.75246 | D35: 0.062988 | E35: 0.014829 | F35: -0.206664 | G35: 0.614718 | H35: -0.488414 | I35: -0.008215 | J35: -0.134985 | K35: 0.004643 | L35: -0.522722 | M35: 1.607947 | N35: 0.534
A36: DMK+ | B36: -0.822546 | C36: 1.081894 | D36: -0.052425 | E36: 0.139423 | F36: -0.332502 | G36: -0.444885 | H36: 0.728787 | I36: 0.019229 | J36: 0.508701 | K36: -0.797986 | L36: -0.618206 | M36: 2.53478 | N36: 0.291
A37: TVK | B37: -0.046508 | C37: -0.329434 | D37: -0.010563 | E37: -0.154252 | F37: 0.539167 | G37: -0.169833 | H37: -0.240372 | I37: -0.011014 | J37: -0.373716 | K37: 0.793343 | L37: 1.140928 | M37: -4.142727 | N37: 0

Sheet District Split
A1: District-wise split: every AC under its district, with the final estimate and the 2026 result
A2: All values are formulas on AC Estimate (looked up by AC No). Subtotal rows compare estimated and actual seats per alliance.
A4: AC No | B4: AC | C4: District | D4: Survey n | E4: AIADMK+ % | F4: DMK+ % | G4: NOTA % | H4: NTK % | I4: TVK % | J4: Saket's call | K4: Final estimate | L4: P(win) | M4: Actual winner (ECI) | N4: Actual alliance | O4: Match?
A5: Ariyalur
A6: 149 | B6: =INDEX('AC Estimate'!$B$5:$B$238,MATCH($A6,'AC Estimate'!$A$5:$A$238,0)) -> Ariyalur | C6: =INDEX('AC Estimate'!$C$5:$C$238,MATCH($A6,'AC Estimate'!$A$5:$A$238,0)) -> Ariyalur | D6: =INDEX('AC Estimate'!$I$5:$I$238,MATCH($A6,'AC Estimate'!$A$5:$A$238,0)) -> 61 | E6: =INDEX('AC Estimate'!$J$5:$J$238,MATCH($A6,'AC Estimate'!$A$5:$A$238,0)) -> 0.26229508 | F6: =INDEX('AC Estimate'!$K$5:$K$238,MATCH($A6,'AC Estimate'!$A$5:$A$238,0)) -> 0.31147541 | G6: =INDEX('AC Estimate'!$L$5:$L$238,MATCH($A6,'AC Estimate'!$A$5:$A$238,0)) -> 0 | H6: =INDEX('AC Estimate'!$M$5:$M$238,MATCH($A6,'AC Estimate'!$A$5:$A$238,0)) -> 0.13114754 | I6: =INDEX('AC Estimate'!$N$5:$N$238,MATCH($A6,'AC Estimate'!$A$5:$A$238,0)) -> 0.29508197 | J6: =INDEX('AC Estimate'!$P$5:$P$238,MATCH($A6,'AC Estimate'!$A$5:$A$238,0)) -> DMK+ | K6: =INDEX('AC Estimate'!$AK$5:$AK$238,MATCH($A6,'AC Estimate'!$A$5:$A$238,0)) -> AIADMK+ | L6: =INDEX('AC Estimate'!$AM$5:$AM$238,MATCH($A6,'AC Estimate'!$A$5:$A$238,0)) -> 0.23524512 | M6: =INDEX('AC Estimate'!$Q$5:$Q$238,MATCH($A6,'AC Estimate'!$A$5:$A$238,0)) -> AIADMK | N6: =INDEX('AC Estimate'!$R$5:$R$238,MATCH($A6,'AC Estimate'!$A$5:$A$238,0)) -> AIADMK+ | O6: =INDEX('AC Estimate'!$AL$5:$AL$238,MATCH($A6,'AC Estimate'!$A$5:$A$238,0)) -> Yes
A7: 150 | B7: =INDEX('AC Estimate'!$B$5:$B$238,MATCH($A7,'AC Estimate'!$A$5:$A$238,0)) -> Jayankondam | C7: =INDEX('AC Estimate'!$C$5:$C$238,MATCH($A7,'AC Estimate'!$A$5:$A$238,0)) -> Ariyalur | D7: =INDEX('AC Estimate'!$I$5:$I$238,MATCH($A7,'AC Estimate'!$A$5:$A$238,0)) -> 32 | E7: =INDEX('AC Estimate'!$J$5:$J$238,MATCH($A7,'AC Estimate'!$A$5:$A$238,0)) -> 0.375 | F7: =INDEX('AC Estimate'!$K$5:$K$238,MATCH($A7,'AC Estimate'!$A$5:$A$238,0)) -> 0.15625 | G7: =INDEX('AC Estimate'!$L$5:$L$238,MATCH($A7,'AC Estimate'!$A$5:$A$238,0)) -> 0 | H7: =INDEX('AC Estimate'!$M$5:$M$238,MATCH($A7,'AC Estimate'!$A$5:$A$238,0)) -> 0.03125 | I7: =INDEX('AC Estimate'!$N$5:$N$238,MATCH($A7,'AC Estimate'!$A$5:$A$238,0)) -> 0.4375 | J7: =INDEX('AC Estimate'!$P$5:$P$238,MATCH($A7,'AC Estimate'!$A$5:$A$238,0)) -> TVK | K7: =INDEX('AC Estimate'!$AK$5:$AK$238,MATCH($A7,'AC Estimate'!$A$5:$A$238,0)) -> AIADMK+ | L7: =INDEX('AC Estimate'!$AM$5:$AM$238,MATCH($A7,'AC Estimate'!$A$5:$A$238,0)) -> 0.41011406 | M7: =INDEX('AC Estimate'!$Q$5:$Q$238,MATCH($A7,'AC Estimate'!$A$5:$A$238,0)) -> PMK | N7: =INDEX('AC Estimate'!$R$5:$R$238,MATCH($A7,'AC Estimate'!$A$5:$A$238,0)) -> AIADMK+ | O7: =INDEX('AC Estimate'!$AL$5:$AL$238,MATCH($A7,'AC Estimate'!$A$5:$A$238,0)) -> Yes
B8: Ariyalur subtotal | D8: =SUM(D6:D7) -> 93 | J8: Est. T/A/D | K8: =COUNTIF(K6:K7,"TVK")&" / "&COUNTIF(K6:K7,"AIADMK+")&" / "&COUNTIF(K6:K7,"DMK+") -> 0 / 2 / 0 | M8: Actual T/A/D | N8: =COUNTIF(N6:N7,"TVK")&" / "&COUNTIF(N6:N7,"AIADMK+")&" / "&COUNTIF(N6:N7,"DMK+") -> 0 / 2 / 0 | O8: =IF(AND(ABS(COUNTIF(K6:K7,"TVK")-COUNTIF(N6:N7,"TVK"))<=Calibration!$B$3,ABS(COUNTIF(K6:K7,"AIADMK+")-COUNTIF(N6:N7,"AIADMK+"))<=Calibration!$B$3,ABS(COUNTIF(K6:K7,"DMK+")-COUNTIF(N6:N7,"DMK+"))<=Calibration!$B$3),"Within","Off") -> Within
A10: Chengalpattu
A11: 30 | B11: =INDEX('AC Estimate'!$B$5:$B$238,MATCH($A11,'AC Estimate'!$A$5:$A$238,0)) -> Pallavaram | C11: =INDEX('AC Estimate'!$C$5:$C$238,MATCH($A11,'AC Estimate'!$A$5:$A$238,0)) -> Chengalpattu | D11: =INDEX('AC Estimate'!$I$5:$I$238,MATCH($A11,'AC Estimate'!$A$5:$A$238,0)) -> 96 | E11: =INDEX('AC Estimate'!$J$5:$J$238,MATCH($A11,'AC Estimate'!$A$5:$A$238,0)) -> 0.27083333 | F11: =INDEX('AC Estimate'!$K$5:$K$238,MATCH($A11,'AC Estimate'!$A$5:$A$238,0)) -> 0.29166667 | G11: =INDEX('AC Estimate'!$L$5:$L$238,MATCH($A11,'AC Estimate'!$A$5:$A$238,0)) -> 0 | H11: =INDEX('AC Estimate'!$M$5:$M$238,MATCH($A11,'AC Estimate'!$A$5:$A$238,0)) -> 0.041666667 | I11: =INDEX('AC Estimate'!$N$5:$N$238,MATCH($A11,'AC Estimate'!$A$5:$A$238,0)) -> 0.39583333 | J11: =INDEX('AC Estimate'!$P$5:$P$238,MATCH($A11,'AC Estimate'!$A$5:$A$238,0)) -> TVK | K11: =INDEX('AC Estimate'!$AK$5:$AK$238,MATCH($A11,'AC Estimate'!$A$5:$A$238,0)) -> TVK | L11: =INDEX('AC Estimate'!$AM$5:$AM$238,MATCH($A11,'AC Estimate'!$A$5:$A$238,0)) -> 0.71848996 | M11: =INDEX('AC Estimate'!$Q$5:$Q$238,MATCH($A11,'AC Estimate'!$A$5:$A$238,0)) -> TVK | N11: =INDEX('AC Estimate'!$R$5:$R$238,MATCH($A11,'AC Estimate'!$A$5:$A$238,0)) -> TVK | O11: =INDEX('AC Estimate'!$AL$5:$AL$238,MATCH($A11,'AC Estimate'!$A$5:$A$238,0)) -> Yes
A12: 31 | B12: =INDEX('AC Estimate'!$B$5:$B$238,MATCH($A12,'AC Estimate'!$A$5:$A$238,0)) -> Tambaram | C12: =INDEX('AC Estimate'!$C$5:$C$238,MATCH($A12,'AC Estimate'!$A$5:$A$238,0)) -> Chengalpattu | D12: =INDEX('AC Estimate'!$I$5:$I$238,MATCH($A12,'AC Estimate'!$A$5:$A$238,0)) -> 97 | E12: =INDEX('AC Estimate'!$J$5:$J$238,MATCH($A12,'AC Estimate'!$A$5:$A$238,0)) -> 0.25773196 | F12: =INDEX('AC Estimate'!$K$5:$K$238,MATCH($A12,'AC Estimate'!$A$5:$A$238,0)) -> 0.34020619 | G12: =INDEX('AC Estimate'!$L$5:$L$238,MATCH($A12,'AC Estimate'!$A$5:$A$238,0)) -> 0.020618557 | H12: =INDEX('AC Estimate'!$M$5:$M$238,MATCH($A12,'AC Estimate'!$A$5:$A$238,0)) -> 0.06185567 | I12: =INDEX('AC Estimate'!$N$5:$N$238,MATCH($A12,'AC Estimate'!$A$5:$A$238,0)) -> 0.31958763 | J12: =INDEX('AC Estimate'!$P$5:$P$238,MATCH($A12,'AC Estimate'!$A$5:$A$238,0)) -> DMK+ | K12: =INDEX('AC Estimate'!$AK$5:$AK$238,MATCH($A12,'AC Estimate'!$A$5:$A$238,0)) -> TVK | L12: =INDEX('AC Estimate'!$AM$5:$AM$238,MATCH($A12,'AC Estimate'!$A$5:$A$238,0)) -> 0.70323505 | M12: =INDEX('AC Estimate'!$Q$5:$Q$238,MATCH($A12,'AC Estimate'!$A$5:$A$238,0)) -> TVK | N12: =INDEX('AC Estimate'!$R$5:$R$238,MATCH($A12,'AC Estimate'!$A$5:$A$238,0)) -> TVK | O12: =INDEX('AC Estimate'!$AL$5:$AL$238,MATCH($A12,'AC Estimate'!$A$5:$A$238,0)) -> Yes
A13: 32 | B13: =INDEX('AC Estimate'!$B$5:$B$238,MATCH($A13,'AC Estimate'!$A$5:$A$238,0)) -> Chengalpattu | C13: =INDEX('AC Estimate'!$C$5:$C$238,MATCH($A13,'AC Estimate'!$A$5:$A$238,0)) -> Chengalpattu | D13: =INDEX('AC Estimate'!$I$5:$I$238,MATCH($A13,'AC Estimate'!$A$5:$A$238,0)) -> 67 | E13: =INDEX('AC Estimate'!$J$5:$J$238,MATCH($A13,'AC Estimate'!$A$5:$A$238,0)) -> 0.19402985 | F13: =INDEX('AC Estimate'!$K$5:$K$238,MATCH($A13,'AC Estimate'!$A$5:$A$238,0)) -> 0.19402985 | G13: =INDEX('AC Estimate'!$L$5:$L$238,MATCH($A13,'AC Estimate'!$A$5:$A$238,0)) -> 0.014925373 | H13: =INDEX('AC Estimate'!$M$5:$M$238,MATCH($A13,'AC Estimate'!$A$5:$A$238,0)) -> 0.074626866 | I13: =INDEX('AC Estimate'!$N$5:$N$238,MATCH($A13,'AC Estimate'!$A$5:$A$238,0)) -> 0.52238806 | J13: =INDEX('AC Estimate'!$P$5:$P$238,MATCH($A13,'AC Estimate'!$A$5:$A$238,0)) -> TVK | K13: =INDEX('AC Estimate'!$AK$5:$AK$238,MATCH($A13,'AC Estimate'!$A$5:$A$238,0)) -> TVK | L13: =INDEX('AC Estimate'!$AM$5:$AM$238,MATCH($A13,'AC Estimate'!$A$5:$A$238,0)) -> 0.61528161 | M13: =INDEX('AC Estimate'!$Q$5:$Q$238,MATCH($A13,'AC Estimate'!$A$5:$A$238,0)) -> TVK | N13: =INDEX('AC Estimate'!$R$5:$R$238,MATCH($A13,'AC Estimate'!$A$5:$A$238,0)) -> TVK | O13: =INDEX('AC Estimate'!$AL$5:$AL$238,MATCH($A13,'AC Estimate'!$A$5:$A$238,0)) -> Yes
A14: 33 | B14: =INDEX('AC Estimate'!$B$5:$B$238,MATCH($A14,'AC Estimate'!$A$5:$A$238,0)) -> Thiruporur | C14: =INDEX('AC Estimate'!$C$5:$C$238,MATCH($A14,'AC Estimate'!$A$5:$A$238,0)) -> Chengalpattu | D14: =INDEX('AC Estimate'!$I$5:$I$238,MATCH($A14,'AC Estimate'!$A$5:$A$238,0)) -> 34 | E14: =INDEX('AC Estimate'!$J$5:$J$238,MATCH($A14,'AC Estimate'!$A$5:$A$238,0)) -> 0.20588235 | F14: =INDEX('AC Estimate'!$K$5:$K$238,MATCH($A14,'AC Estimate'!$A$5:$A$238,0)) -> 0.058823529 | G14: =INDEX('AC Estimate'!$L$5:$L$238,MATCH($A14,'AC Estimate'!$A$5:$A$238,0)) -> 0 | H14: =INDEX('AC Estimate'!$M$5:$M$238,MATCH($A14,'AC Estimate'!$A$5:$A$238,0)) -> 0.14705882 | I14: =INDEX('AC Estimate'!$N$5:$N$238,MATCH($A14,'AC Estimate'!$A$5:$A$238,0)) -> 0.58823529 | J14: =INDEX('AC Estimate'!$P$5:$P$238,MATCH($A14,'AC Estimate'!$A$5:$A$238,0)) -> TVK | K14: =INDEX('AC Estimate'!$AK$5:$AK$238,MATCH($A14,'AC Estimate'!$A$5:$A$238,0)) -> TVK | L14: =INDEX('AC Estimate'!$AM$5:$AM$238,MATCH($A14,'AC Estimate'!$A$5:$A$238,0)) -> 0.35564196 | M14: =INDEX('AC Estimate'!$Q$5:$Q$238,MATCH($A14,'AC Estimate'!$A$5:$A$238,0)) -> TVK | N14: =INDEX('AC Estimate'!$R$5:$R$238,MATCH($A14,'AC Estimate'!$A$5:$A$238,0)) -> TVK | O14: =INDEX('AC Estimate'!$AL$5:$AL$238,MATCH($A14,'AC Estimate'!$A$5:$A$238,0)) -> Yes
A15: 34 | B15: =INDEX('AC Estimate'!$B$5:$B$238,MATCH($A15,'AC Estimate'!$A$5:$A$238,0)) -> Cheyyur | C15: =INDEX('AC Estimate'!$C$5:$C$238,MATCH($A15,'AC Estimate'!$A$5:$A$238,0)) -> Chengalpattu | D15: =INDEX('AC Estimate'!$I$5:$I$238,MATCH($A15,'AC Estimate'!$A$5:$A$238,0)) -> 22 | E15: =INDEX('AC Estimate'!$J$5:$J$238,MATCH($A15,'AC Estimate'!$A$5:$A$238,0)) -> 0.54545455 | F15: =INDEX('AC Estimate'!$K$5:$K$238,MATCH($A15,'AC Estimate'!$A$5:$A$238,0)) -> 0.13636364 | G15: =INDEX('AC Estimate'!$L$5:$L$238,MATCH($A15,'AC Estimate'!$A$5:$A$238,0)) -> 0 | H15: =INDEX('AC Estimate'!$M$5:$M$238,MATCH($A15,'AC Estimate'!$A$5:$A$238,0)) -> 0.045454545 | I15: =INDEX('AC Estimate'!$N$5:$N$238,MATCH($A15,'AC Estimate'!$A$5:$A$238,0)) -> 0.27272727 | J15: =INDEX('AC Estimate'!$P$5:$P$238,MATCH($A15,'AC Estimate'!$A$5:$A$238,0)) -> AIADMK+ | K15: =INDEX('AC Estimate'!$AK$5:$AK$238,MATCH($A15,'AC Estimate'!$A$5:$A$238,0)) -> AIADMK+ | L15: =INDEX('AC Estimate'!$AM$5:$AM$238,MATCH($A15,'AC Estimate'!$A$5:$A$238,0)) -> 0.53902691 | M15: =INDEX('AC Estimate'!$Q$5:$Q$238,MATCH($A15,'AC Estimate'!$A$5:$A$238,0)) -> AIADMK | N15: =INDEX('AC Estimate'!$R$5:$R$238,MATCH($A15,'AC Estimate'!$A$5:$A$238,0)) -> AIADMK+ | O15: =INDEX('AC Estimate'!$AL$5:$AL$238,MATCH($A15,'AC Estimate'!$A$5:$A$238,0)) -> Yes
A16: 35 | B16: =INDEX('AC Estimate'!$B$5:$B$238,MATCH($A16,'AC Estimate'!$A$5:$A$238,0)) -> Madurantakam | C16: =INDEX('AC Estimate'!$C$5:$C$238,MATCH($A16,'AC Estimate'!$A$5:$A$238,0)) -> Chengalpattu | D16: =INDEX('AC Estimate'!$I$5:$I$238,MATCH($A16,'AC Estimate'!$A$5:$A$238,0)) -> 18 | E16: =INDEX('AC Estimate'!$J$5:$J$238,MATCH($A16,'AC Estimate'!$A$5:$A$238,0)) -> 0.27777778 | F16: =INDEX('AC Estimate'!$K$5:$K$238,MATCH($A16,'AC Estimate'!$A$5:$A$238,0)) -> 0.22222222 | G16: =INDEX('AC Estimate'!$L$5:$L$238,MATCH($A16,'AC Estimate'!$A$5:$A$238,0)) -> 0 | H16: =INDEX('AC Estimate'!$M$5:$M$238,MATCH($A16,'AC Estimate'!$A$5:$A$238,0)) -> 0.055555556 | I16: =INDEX('AC Estimate'!$N$5:$N$238,MATCH($A16,'AC Estimate'!$A$5:$A$238,0)) -> 0.44444444 | J16: =INDEX('AC Estimate'!$P$5:$P$238,MATCH($A16,'AC Estimate'!$A$5:$A$238,0)) -> TVK | K16: =INDEX('AC Estimate'!$AK$5:$AK$238,MATCH($A16,'AC Estimate'!$A$5:$A$238,0)) -> AIADMK+ | L16: =INDEX('AC Estimate'!$AM$5:$AM$238,MATCH($A16,'AC Estimate'!$A$5:$A$238,0)) -> 0.42584818 | M16: =INDEX('AC Estimate'!$Q$5:$Q$238,MATCH($A16,'AC Estimate'!$A$5:$A$238,0)) -> AIADMK | N16: =INDEX('AC Estimate'!$R$5:$R$238,MATCH($A16,'AC Estimate'!$A$5:$A$238,0)) -> AIADMK+ | O16: =INDEX('AC Estimate'!$AL$5:$AL$238,MATCH($A16,'AC Estimate'!$A$5:$A$238,0)) -> Yes
B17: Chengalpattu subtotal | D17: =SUM(D11:D16) -> 334 | J17: Est. T/A/D | K17: =COUNTIF(K11:K16,"TVK")&" / "&COUNTIF(K11:K16,"AIADMK+")&" / "&COUNTIF(K11:K16,"DMK+") -> 4 / 2 / 0 | M17: Actual T/A/D | N17: =COUNTIF(N11:N16,"TVK")&" / "&COUNTIF(N11:N16,"AIADMK+")&" / "&COUNTIF(N11:N16,"DMK+") -> 4 / 2 / 0 | O17: =IF(AND(ABS(COUNTIF(K11:K16,"TVK")-COUNTIF(N11:N16,"TVK"))<=Calibration!$B$3,ABS(COUNTIF(K11:K16,"AIADMK+")-COUNTIF(N11:N16,"AIADMK+"))<=Calibration!$B$3,ABS(COUNTIF(K11:K16,"DMK+")-COUNTIF(N11:N16,"DMK+"))<=Calibration!$B$3),"Within","Off") -> Within
A19: Chennai
A20: 7 | B20: =INDEX('AC Estimate'!$B$5:$B$238,MATCH($A20,'AC Estimate'!$A$5:$A$238,0)) -> Maduravoyal | C20: =INDEX('AC Estimate'!$C$5:$C$238,MATCH($A20,'AC Estimate'!$A$5:$A$238,0)) -> Chennai | D20: =INDEX('AC Estimate'!$I$5:$I$238,MATCH($A20,'AC Estimate'!$A$5:$A$238,0)) -> 105 | E20: =INDEX('AC Estimate'!$J$5:$J$238,MATCH($A20,'AC Estimate'!$A$5:$A$238,0)) -> 0.26666667 | F20: =INDEX('AC Estimate'!$K$5:$K$238,MATCH($A20,'AC Estimate'!$A$5:$A$238,0)) -> 0.19047619 | G20: =INDEX('AC Estimate'!$L$5:$L$238,MATCH($A20,'AC Estimate'!$A$5:$A$238,0)) -> 0.019047619 | H20: =INDEX('AC Estimate'!$M$5:$M$238,MATCH($A20,'AC Estimate'!$A$5:$A$238,0)) -> 0.057142857 | I20: =INDEX('AC Estimate'!$N$5:$N$238,MATCH($A20,'AC Estimate'!$A$5:$A$238,0)) -> 0.46666667 | J20: =INDEX('AC Estimate'!$P$5:$P$238,MATCH($A20,'AC Estimate'!$A$5:$A$238,0)) -> TVK | K20: =INDEX('AC Estimate'!$AK$5:$AK$238,MATCH($A20,'AC Estimate'!$A$5:$A$238,0)) -> TVK | L20: =INDEX('AC Estimate'!$AM$5:$AM$238,MATCH($A20,'AC Estimate'!$A$5:$A$238,0)) -> 0.76783506 | M20: =INDEX('AC Estimate'!$Q$5:$Q$238,MATCH($A20,'AC Estimate'!$A$5:$A$238,0)) -> TVK | N20: =INDEX('AC Estimate'!$R$5:$R$238,MATCH($A20,'AC Estimate'!$A$5:$A$238,0)) -> TVK | O20: =INDEX('AC Estimate'!$AL$5:$AL$238,MATCH($A20,'AC Estimate'!$A$5:$A$238,0)) -> Yes
A21: 8 | B21: =INDEX('AC Estimate'!$B$5:$B$238,MATCH($A21,'AC Estimate'!$A$5:$A$238,0)) -> Ambattur | C21: =INDEX('AC Estimate'!$C$5:$C$238,MATCH($A21,'AC Estimate'!$A$5:$A$238,0)) -> Chennai | D21: =INDEX('AC Estimate'!$I$5:$I$238,MATCH($A21,'AC Estimate'!$A$5:$A$238,0)) -> 87 | E21: =INDEX('AC Estimate'!$J$5:$J$238,MATCH($A21,'AC Estimate'!$A$5:$A$238,0)) -> 0.28735632 | F21: =INDEX('AC Estimate'!$K$5:$K$238,MATCH($A21,'AC Estimate'!$A$5:$A$238,0)) -> 0.25287356 | G21: =INDEX('AC Estimate'!$L$5:$L$238,MATCH($A21,'AC Estimate'!$A$5:$A$238,0)) -> 0.034482759 | H21: =INDEX('AC Estimate'!$M$5:$M$238,MATCH($A21,'AC Estimate'!$A$5:$A$238,0)) -> 0.057471264 | I21: =INDEX('AC Estimate'!$N$5:$N$238,MATCH($A21,'AC Estimate'!$A$5:$A$238,0)) -> 0.36781609 | J21: =INDEX('AC Estimate'!$P$5:$P$238,MATCH($A21,'AC Estimate'!$A$5:$A$238,0)) -> TVK | K21: =INDEX('AC Estimate'!$AK$5:$AK$238,MATCH($A21,'AC Estimate'!$A$5:$A$238,0)) -> TVK | L21: =INDEX('AC Estimate'!$AM$5:$AM$238,MATCH($A21,'AC Estimate'!$A$5:$A$238,0)) -> 0.68237897 | M21: =INDEX('AC Estimate'!$Q$5:$Q$238,MATCH($A21,'AC Estimate'!$A$5:$A$238,0)) -> TVK | N21: =INDEX('AC Estimate'!$R$5:$R$238,MATCH($A21,'AC Estimate'!$A$5:$A$238,0)) -> TVK | O21: =INDEX('AC Estimate'!$AL$5:$AL$238,MATCH($A21,'AC Estimate'!$A$5:$A$238,0)) -> Yes
A22: 9 | B22: =INDEX('AC Estimate'!$B$5:$B$238,MATCH($A22,'AC Estimate'!$A$5:$A$238,0)) -> Madavaram | C22: =INDEX('AC Estimate'!$C$5:$C$238,MATCH($A22,'AC Estimate'!$A$5:$A$238,0)) -> Chennai | D22: =INDEX('AC Estimate'!$I$5:$I$238,MATCH($A22,'AC Estimate'!$A$5:$A$238,0)) -> 78 | E22: =INDEX('AC Estimate'!$J$5:$J$238,MATCH($A22,'AC Estimate'!$A$5:$A$238,0)) -> 0.28205128 | F22: =INDEX('AC Estimate'!$K$5:$K$238,MATCH($A22,'AC Estimate'!$A$5:$A$238,0)) -> 0.20512821 | G22: =INDEX('AC Estimate'!$L$5:$L$238,MATCH($A22,'AC Estimate'!$A$5:$A$238,0)) -> 0 | H22: =INDEX('AC Estimate'!$M$5:$M$238,MATCH($A22,'AC Estimate'!$A$5:$A$238,0)) -> 0.076923077 | I22: =INDEX('AC Estimate'!$N$5:$N$238,MATCH($A22,'AC Estimate'!$A$5:$A$238,0)) -> 0.43589744 | J22: =INDEX('AC Estimate'!$P$5:$P$238,MATCH($A22,'AC Estimate'!$A$5:$A$238,0)) -> TVK | K22: =INDEX('AC Estimate'!$AK$5:$AK$238,MATCH($A22,'AC Estimate'!$A$5:$A$238,0)) -> TVK | L22: =INDEX('AC Estimate'!$AM$5:$AM$238,MATCH($A22,'AC Estimate'!$A$5:$A$238,0)) -> 0.65730553 | M22: =INDEX('AC Estimate'!$Q$5:$Q$238,MATCH($A22,'AC Estimate'!$A$5:$A$238,0)) -> TVK | N22: =INDEX('AC Estimate'!$R$5:$R$238,MATCH($A22,'AC Estimate'!$A$5:$A$238,0)) -> TVK | O22: =INDEX('AC Estimate'!$AL$5:$AL$238,MATCH($A22,'AC Estimate'!$A$5:$A$238,0)) -> Yes
A23: 10 | B23: =INDEX('AC Estimate'!$B$5:$B$238,MATCH($A23,'AC Estimate'!$A$5:$A$238,0)) -> Thiruvottiyur | C23: =INDEX('AC Estimate'!$C$5:$C$238,MATCH($A23,'AC Estimate'!$A$5:$A$238,0)) -> Chennai | D23: =INDEX('AC Estimate'!$I$5:$I$238,MATCH($A23,'AC Estimate'!$A$5:$A$238,0)) -> 53 | E23: =INDEX('AC Estimate'!$J$5:$J$238,MATCH($A23,'AC Estimate'!$A$5:$A$238,0)) -> 0.20754717 | F23: =INDEX('AC Estimate'!$K$5:$K$238,MATCH($A23,'AC Estimate'!$A$5:$A$238,0)) -> 0.35849057 | G23: =INDEX('AC Estimate'!$L$5:$L$238,MATCH($A23,'AC Estimate'!$A$5:$A$238,0)) -> 0 | H23: =INDEX('AC Estimate'!$M$5:$M$238,MATCH($A23,'AC Estimate'!$A$5:$A$238,0)) -> 0.094339623 | I23: =INDEX('AC Estimate'!$N$5:$N$238,MATCH($A23,'AC Estimate'!$A$5:$A$238,0)) -> 0.33962264 | J23: =INDEX('AC Estimate'!$P$5:$P$238,MATCH($A23,'AC Estimate'!$A$5:$A$238,0)) -> DMK+ | K23: =INDEX('AC Estimate'!$AK$5:$AK$238,MATCH($A23,'AC Estimate'!$A$5:$A$238,0)) -> TVK | L23: =INDEX('AC Estimate'!$AM$5:$AM$238,MATCH($A23,'AC Estimate'!$A$5:$A$238,0)) -> 0.45655829 | M23: =INDEX('AC Estimate'!$Q$5:$Q$238,MATCH($A23,'AC Estimate'!$A$5:$A$238,0)) -> TVK | N23: =INDEX('AC Estimate'!$R$5:$R$238,MATCH($A23,'AC Estimate'!$A$5:$A$238,0)) -> TVK | O23: =INDEX('AC Estimate'!$AL$5:$AL$238,MATCH($A23,'AC Estimate'!$A$5:$A$238,0)) -> Yes
A24: 11 | B24: =INDEX('AC Estimate'!$B$5:$B$238,MATCH($A24,'AC Estimate'!$A$5:$A$238,0)) -> Dr. Radhakrishnan Nagar | C24: =INDEX('AC Estimate'!$C$5:$C$238,MATCH($A24,'AC Estimate'!$A$5:$A$238,0)) -> Chennai | D24: =INDEX('AC Estimate'!$I$5:$I$238,MATCH($A24,'AC Estimate'!$A$5:$A$238,0)) -> 54 | E24: =INDEX('AC Estimate'!$J$5:$J$238,MATCH($A24,'AC Estimate'!$A$5:$A$238,0)) -> 0.18518519 | F24: =INDEX('AC Estimate'!$K$5:$K$238,MATCH($A24,'AC Estimate'!$A$5:$A$238,0)) -> 0.2962963 | G24: =INDEX('AC Estimate'!$L$5:$L$238,MATCH($A24,'AC Estimate'!$A$5:$A$238,0)) -> 0 | H24: =INDEX('AC Estimate'!$M$5:$M$238,MATCH($A24,'AC Estimate'!$A$5:$A$238,0)) -> 0.055555556 | I24: =INDEX('AC Estimate'!$N$5:$N$238,MATCH($A24,'AC Estimate'!$A$5:$A$238,0)) -> 0.46296296 | J24: =INDEX('AC Estimate'!$P$5:$P$238,MATCH($A24,'AC Estimate'!$A$5:$A$238,0)) -> TVK | K24: =INDEX('AC Estimate'!$AK$5:$AK$238,MATCH($A24,'AC Estimate'!$A$5:$A$238,0)) -> TVK | L24: =INDEX('AC Estimate'!$AM$5:$AM$238,MATCH($A24,'AC Estimate'!$A$5:$A$238,0)) -> 0.50142845 | M24: =INDEX('AC Estimate'!$Q$5:$Q$238,MATCH($A24,'AC Estimate'!$A$5:$A$238,0)) -> TVK | N24: =INDEX('AC Estimate'!$R$5:$R$238,MATCH($A24,'AC Estimate'!$A$5:$A$238,0)) -> TVK | O24: =INDEX('AC Estimate'!$AL$5:$AL$238,MATCH($A24,'AC Estimate'!$A$5:$A$238,0)) -> Yes
A25: 12 | B25: =INDEX('AC Estimate'!$B$5:$B$238,MATCH($A25,'AC Estimate'!$A$5:$A$238,0)) -> Perambur | C25: =INDEX('AC Estimate'!$C$5:$C$238,MATCH($A25,'AC Estimate'!$A$5:$A$238,0)) -> Chennai | D25: =INDEX('AC Estimate'!$I$5:$I$238,MATCH($A25,'AC Estimate'!$A$5:$A$238,0)) -> 95 | E25: =INDEX('AC Estimate'!$J$5:$J$238,MATCH($A25,'AC Estimate'!$A$5:$A$238,0)) -> 0.094736842 | F25: =INDEX('AC Estimate'!$K$5:$K$238,MATCH($A25,'AC Estimate'!$A$5:$A$238,0)) -> 0.23157895 | G25: =INDEX('AC Estimate'!$L$5:$L$238,MATCH($A25,'AC Estimate'!$A$5:$A$238,0)) -> 0 | H25: =INDEX('AC Estimate'!$M$5:$M$238,MATCH($A25,'AC Estimate'!$A$5:$A$238,0)) -> 0.042105263 | I25: =INDEX('AC Estimate'!$N$5:$N$238,MATCH($A25,'AC Estimate'!$A$5:$A$238,0)) -> 0.63157895 | J25: =INDEX('AC Estimate'!$P$5:$P$238,MATCH($A25,'AC Estimate'!$A$5:$A$238,0)) -> TVK | K25: =INDEX('AC Estimate'!$AK$5:$AK$238,MATCH($A25,'AC Estimate'!$A$5:$A$238,0)) -> TVK | L25: =INDEX('AC Estimate'!$AM$5:$AM$238,MATCH($A25,'AC Estimate'!$A$5:$A$238,0)) -> 0.75996508 | M25: =INDEX('AC Estimate'!$Q$5:$Q$238,MATCH($A25,'AC Estimate'!$A$5:$A$238,0)) -> TVK | N25: =INDEX('AC Estimate'!$R$5:$R$238,MATCH($A25,'AC Estimate'!$A$5:$A$238,0)) -> TVK | O25: =INDEX('AC Estimate'!$AL$5:$AL$238,MATCH($A25,'AC Estimate'!$A$5:$A$238,0)) -> Yes
A26: 13 | B26: =INDEX('AC Estimate'!$B$5:$B$238,MATCH($A26,'AC Estimate'!$A$5:$A$238,0)) -> Kolathur | C26: =INDEX('AC Estimate'!$C$5:$C$238,MATCH($A26,'AC Estimate'!$A$5:$A$238,0)) -> Chennai | D26: =INDEX('AC Estimate'!$I$5:$I$238,MATCH($A26,'AC Estimate'!$A$5:$A$238,0)) -> 63 | E26: =INDEX('AC Estimate'!$J$5:$J$238,MATCH($A26,'AC Estimate'!$A$5:$A$238,0)) -> 0.23809524 | F26: =INDEX('AC Estimate'!$K$5:$K$238,MATCH($A26,'AC Estimate'!$A$5:$A$238,0)) -> 0.22222222 | G26: =INDEX('AC Estimate'!$L$5:$L$238,MATCH($A26,'AC Estimate'!$A$5:$A$238,0)) -> 0.015873016 | H26: =INDEX('AC Estimate'!$M$5:$M$238,MATCH($A26,'AC Estimate'!$A$5:$A$238,0)) -> 0 | I26: =INDEX('AC Estimate'!$N$5:$N$238,MATCH($A26,'AC Estimate'!$A$5:$A$238,0)) -> 0.52380952 | J26: =INDEX('AC Estimate'!$P$5:$P$238,MATCH($A26,'AC Estimate'!$A$5:$A$238,0)) -> TVK | K26: =INDEX('AC Estimate'!$AK$5:$AK$238,MATCH($A26,'AC Estimate'!$A$5:$A$238,0)) -> TVK | L26: =INDEX('AC Estimate'!$AM$5:$AM$238,MATCH($A26,'AC Estimate'!$A$5:$A$238,0)) -> 0.59170004 | M26: =INDEX('AC Estimate'!$Q$5:$Q$238,MATCH($A26,'AC Estimate'!$A$5:$A$238,0)) -> TVK | N26: =INDEX('AC Estimate'!$R$5:$R$238,MATCH($A26,'AC Estimate'!$A$5:$A$238,0)) -> TVK | O26: =INDEX('AC Estimate'!$AL$5:$AL$238,MATCH($A26,'AC Estimate'!$A$5:$A$238,0)) -> Yes
A27: 14 | B27: =INDEX('AC Estimate'!$B$5:$B$238,MATCH($A27,'AC Estimate'!$A$5:$A$238,0)) -> Villivakkam | C27: =INDEX('AC Estimate'!$C$5:$C$238,MATCH($A27,'AC Estimate'!$A$5:$A$238,0)) -> Chennai | D27: =INDEX('AC Estimate'!$I$5:$I$238,MATCH($A27,'AC Estimate'!$A$5:$A$238,0)) -> 55 | E27: =INDEX('AC Estimate'!$J$5:$J$238,MATCH($A27,'AC Estimate'!$A$5:$A$238,0)) -> 0.090909091 | F27: =INDEX('AC Estimate'!$K$5:$K$238,MATCH($A27,'AC Estimate'!$A$5:$A$238,0)) -> 0.47272727 | G27: =INDEX('AC Estimate'!$L$5:$L$238,MATCH($A27,'AC Estimate'!$A$5:$A$238,0)) -> 0 | H27: =INDEX('AC Estimate'!$M$5:$M$238,MATCH($A27,'AC Estimate'!$A$5:$A$238,0)) -> 0.036363636 | I27: =INDEX('AC Estimate'!$N$5:$N$238,MATCH($A27,'AC Estimate'!$A$5:$A$238,0)) -> 0.4 | J27: =INDEX('AC Estimate'!$P$5:$P$238,MATCH($A27,'AC Estimate'!$A$5:$A$238,0)) -> DMK+ | K27: =INDEX('AC Estimate'!$AK$5:$AK$238,MATCH($A27,'AC Estimate'!$A$5:$A$238,0)) -> TVK | L27: =INDEX('AC Estimate'!$AM$5:$AM$238,MATCH($A27,'AC Estimate'!$A$5:$A$238,0)) -> 0.46338838 | M27: =INDEX('AC Estimate'!$Q$5:$Q$238,MATCH($A27,'AC Estimate'!$A$5:$A$238,0)) -> TVK | N27: =INDEX('AC Estimate'!$R$5:$R$238,MATCH($A27,'AC Estimate'!$A$5:$A$238,0)) -> TVK | O27: =INDEX('AC Estimate'!$AL$5:$AL$238,MATCH($A27,'AC Estimate'!$A$5:$A$238,0)) -> Yes
A28: 15 | B28: =INDEX('AC Estimate'!$B$5:$B$238,MATCH($A28,'AC Estimate'!$A$5:$A$238,0)) -> Thiru-Vi-Ka-Nagar | C28: =INDEX('AC Estimate'!$C$5:$C$238,MATCH($A28,'AC Estimate'!$A$5:$A$238,0)) -> Chennai | D28: =INDEX('AC Estimate'!$I$5:$I$238,MATCH($A28,'AC Estimate'!$A$5:$A$238,0)) -> 24 | E28: =INDEX('AC Estimate'!$J$5:$J$238,MATCH($A28,'AC Estimate'!$A$5:$A$238,0)) -> 0.16666667 | F28: =INDEX('AC Estimate'!$K$5:$K$238,MATCH($A28,'AC Estimate'!$A$5:$A$238,0)) -> 0.125 | G28: =INDEX('AC Estimate'!$L$5:$L$238,MATCH($A28,'AC Estimate'!$A$5:$A$238,0)) -> 0 | H28: =INDEX('AC Estimate'!$M$5:$M$238,MATCH($A28,'AC Estimate'!$A$5:$A$238,0)) -> 0.041666667 | I28: =INDEX('AC Estimate'!$N$5:$N$238,MATCH($A28,'AC Estimate'!$A$5:$A$238,0)) -> 0.66666667 | J28: =INDEX('AC Estimate'!$P$5:$P$238,MATCH($A28,'AC Estimate'!$A$5:$A$238,0)) -> TVK | K28: =INDEX('AC Estimate'!$AK$5:$AK$238,MATCH($A28,'AC Estimate'!$A$5:$A$238,0)) -> DMK+ | L28: =INDEX('AC Estimate'!$AM$5:$AM$238,MATCH($A28,'AC Estimate'!$A$5:$A$238,0)) -> 0.37728897 | M28: =INDEX('AC Estimate'!$Q$5:$Q$238,MATCH($A28,'AC Estimate'!$A$5:$A$238,0)) -> TVK | N28: =INDEX('AC Estimate'!$R$5:$R$238,MATCH($A28,'AC Estimate'!$A$5:$A$238,0)) -> TVK | O28: =INDEX('AC Estimate'!$AL$5:$AL$238,MATCH($A28,'AC Estimate'!$A$5:$A$238,0)) -> No
A29: 16 | B29: =INDEX('AC Estimate'!$B$5:$B$238,MATCH($A29,'AC Estimate'!$A$5:$A$238,0)) -> Egmore | C29: =INDEX('AC Estimate'!$C$5:$C$238,MATCH($A29,'AC Estimate'!$A$5:$A$238,0)) -> Chennai | D29: =INDEX('AC Estimate'!$I$5:$I$238,MATCH($A29,'AC Estimate'!$A$5:$A$238,0)) -> 50 | E29: =INDEX('AC Estimate'!$J$5:$J$238,MATCH($A29,'AC Estimate'!$A$5:$A$238,0)) -> 0.16 | F29: =INDEX('AC Estimate'!$K$5:$K$238,MATCH($A29,'AC Estimate'!$A$5:$A$238,0)) -> 0.44 | G29: =INDEX('AC Estimate'!$L$5:$L$238,MATCH($A29,'AC Estimate'!$A$5:$A$238,0)) -> 0 | H29: =INDEX('AC Estimate'!$M$5:$M$238,MATCH($A29,'AC Estimate'!$A$5:$A$238,0)) -> 0.02 | I29: =INDEX('AC Estimate'!$N$5:$N$238,MATCH($A29,'AC Estimate'!$A$5:$A$238,0)) -> 0.38 | J29: =INDEX('AC Estimate'!$P$5:$P$238,MATCH($A29,'AC Estimate'!$A$5:$A$238,0)) -> DMK+ | K29: =INDEX('AC Estimate'!$AK$5:$AK$238,MATCH($A29,'AC Estimate'!$A$5:$A$238,0)) -> TVK | L29: =INDEX('AC Estimate'!$AM$5:$AM$238,MATCH($A29,'AC Estimate'!$A$5:$A$238,0)) -> 0.42920544 | M29: =INDEX('AC Estimate'!$Q$5:$Q$238,MATCH($A29,'AC Estimate'!$A$5:$A$238,0)) -> TVK | N29: =INDEX('AC Estimate'!$R$5:$R$238,MATCH($A29,'AC Estimate'!$A$5:$A$238,0)) -> TVK | O29: =INDEX('AC Estimate'!$AL$5:$AL$238,MATCH($A29,'AC Estimate'!$A$5:$A$238,0)) -> Yes
A30: 17 | B30: =INDEX('AC Estimate'!$B$5:$B$238,MATCH($A30,'AC Estimate'!$A$5:$A$238,0)) -> Royapuram | C30: =INDEX('AC Estimate'!$C$5:$C$238,MATCH($A30,'AC Estimate'!$A$5:$A$238,0)) -> Chennai | D30: =INDEX('AC Estimate'!$I$5:$I$238,MATCH($A30,'AC Estimate'!$A$5:$A$238,0)) -> 36 | E30: =INDEX('AC Estimate'!$J$5:$J$238,MATCH($A30,'AC Estimate'!$A$5:$A$238,0)) -> 0.25 | F30: =INDEX('AC Estimate'!$K$5:$K$238,MATCH($A30,'AC Estimate'!$A$5:$A$238,0)) -> 0.41666667 | G30: =INDEX('AC Estimate'!$L$5:$L$238,MATCH($A30,'AC Estimate'!$A$5:$A$238,0)) -> 0 | H30: =INDEX('AC Estimate'!$M$5:$M$238,MATCH($A30,'AC Estimate'!$A$5:$A$238,0)) -> 0 | I30: =INDEX('AC Estimate'!$N$5:$N$238,MATCH($A30,'AC Estimate'!$A$5:$A$238,0)) -> 0.33333333 | J30: =INDEX('AC Estimate'!$P$5:$P$238,MATCH($A30,'AC Estimate'!$A$5:$A$238,0)) -> DMK+ | K30: =INDEX('AC Estimate'!$AK$5:$AK$238,MATCH($A30,'AC Estimate'!$A$5:$A$238,0)) -> TVK | L30: =INDEX('AC Estimate'!$AM$5:$AM$238,MATCH($A30,'AC Estimate'!$A$5:$A$238,0)) -> 0.29806048 | M30: =INDEX('AC Estimate'!$Q$5:$Q$238,MATCH($A30,'AC Estimate'!$A$5:$A$238,0)) -> TVK | N30: =INDEX('AC Estimate'!$R$5:$R$238,MATCH($A30,'AC Estimate'!$A$5:$A$238,0)) -> TVK | O30: =INDEX('AC Estimate'!$AL$5:$AL$238,MATCH($A30,'AC Estimate'!$A$5:$A$238,0)) -> Yes
A31: 18 | B31: =INDEX('AC Estimate'!$B$5:$B$238,MATCH($A31,'AC Estimate'!$A$5:$A$238,0)) -> Harbour | C31: =INDEX('AC Estimate'!$C$5:$C$238,MATCH($A31,'AC Estimate'!$A$5:$A$238,0)) -> Chennai | D31: =INDEX('AC Estimate'!$I$5:$I$238,MATCH($A31,'AC Estimate'!$A$5:$A$238,0)) -> 40 | E31: =INDEX('AC Estimate'!$J$5:$J$238,MATCH($A31,'AC Estimate'!$A$5:$A$238,0)) -> 0.25 | F31: =INDEX('AC Estimate'!$K$5:$K$238,MATCH($A31,'AC Estimate'!$A$5:$A$238,0)) -> 0.5 | G31: =INDEX('AC Estimate'!$L$5:$L$238,MATCH($A31,'AC Estimate'!$A$5:$A$238,0)) -> 0 | H31: =INDEX('AC Estimate'!$M$5:$M$238,MATCH($A31,'AC Estimate'!$A$5:$A$238,0)) -> 0.025 | I31: =INDEX('AC Estimate'!$N$5:$N$238,MATCH($A31,'AC Estimate'!$A$5:$A$238,0)) -> 0.225 | J31: =INDEX('AC Estimate'!$P$5:$P$238,MATCH($A31,'AC Estimate'!$A$5:$A$238,0)) -> DMK+ | K31: =INDEX('AC Estimate'!$AK$5:$AK$238,MATCH($A31,'AC Estimate'!$A$5:$A$238,0)) -> DMK+ | L31: =INDEX('AC Estimate'!$AM$5:$AM$238,MATCH($A31,'AC Estimate'!$A$5:$A$238,0)) -> 0.44189875 | M31: =INDEX('AC Estimate'!$Q$5:$Q$238,MATCH($A31,'AC Estimate'!$A$5:$A$238,0)) -> DMK | N31: =INDEX('AC Estimate'!$R$5:$R$238,MATCH($A31,'AC Estimate'!$A$5:$A$238,0)) -> DMK+ | O31: =INDEX('AC Estimate'!$AL$5:$AL$238,MATCH($A31,'AC Estimate'!$A$5:$A$238,0)) -> Yes
... A41: 28 | B41: =INDEX('AC Estimate'!$B$5:$B$238,MATCH($A41,'AC Estimate'!$A$5:$A$238,0)) -> Alandur | C41: =INDEX('AC Estimate'!$C$5:$C$238,MATCH($A41,'AC Estimate'!$A$5:$A$238,0)) -> Chennai | D41: =INDEX('AC Estimate'!$I$5:$I$238,MATCH($A41,'AC Estimate'!$A$5:$A$238,0)) -> 56 | E41: =INDEX('AC Estimate'!$J$5:$J$238,MATCH($A41,'AC Estimate'!$A$5:$A$238,0)) -> 0.41071429 | F41: =INDEX('AC Estimate'!$K$5:$K$238,MATCH($A41,'AC Estimate'!$A$5:$A$238,0)) -> 0.25 | G41: =INDEX('AC Estimate'!$L$5:$L$238,MATCH($A41,'AC Estimate'!$A$5:$A$238,0)) -> 0 | H41: =INDEX('AC Estimate'!$M$5:$M$238,MATCH($A41,'AC Estimate'!$A$5:$A$238,0)) -> 0.053571429 | I41: =INDEX('AC Estimate'!$N$5:$N$238,MATCH($A41,'AC Estimate'!$A$5:$A$238,0)) -> 0.28571429 | J41: =INDEX('AC Estimate'!$P$5:$P$238,MATCH($A41,'AC Estimate'!$A$5:$A$238,0)) -> AIADMK+ | K41: =INDEX('AC Estimate'!$AK$5:$AK$238,MATCH($A41,'AC Estimate'!$A$5:$A$238,0)) -> TVK | L41: =INDEX('AC Estimate'!$AM$5:$AM$238,MATCH($A41,'AC Estimate'!$A$5:$A$238,0)) -> 0.48333033 | M41: =INDEX('AC Estimate'!$Q$5:$Q$238,MATCH($A41,'AC Estimate'!$A$5:$A$238,0)) -> TVK | N41: =INDEX('AC Estimate'!$R$5:$R$238,MATCH($A41,'AC Estimate'!$A$5:$A$238,0)) -> TVK | O41: =INDEX('AC Estimate'!$AL$5:$AL$238,MATCH($A41,'AC Estimate'!$A$5:$A$238,0)) -> Yes
B42: Chennai subtotal | D42: =SUM(D20:D41) -> 1286 | J42: Est. T/A/D | K42: =COUNTIF(K20:K41,"TVK")&" / "&COUNTIF(K20:K41,"AIADMK+")&" / "&COUNTIF(K20:K41,"DMK+") -> 20 / 0 / 2 | M42: Actual T/A/D | N42: =COUNTIF(N20:N41,"TVK")&" / "&COUNTIF(N20:N41,"AIADMK+")&" / "&COUNTIF(N20:N41,"DMK+") -> 20 / 0 / 2 | O42: =IF(AND(ABS(COUNTIF(K20:K41,"TVK")-COUNTIF(N20:N41,"TVK"))<=Calibration!$B$3,ABS(COUNTIF(K20:K41,"AIADMK+")-COUNTIF(N20:N41,"AIADMK+"))<=Calibration!$B$3,ABS(COUNTIF(K20:K41,"DMK+")-COUNTIF(N20:N41,"DMK+"))<=Calibration!$B$3),"Within","Off") -> Within
A44: Coimbatore
A45: 111 | B45: =INDEX('AC Estimate'!$B$5:$B$238,MATCH($A45,'AC Estimate'!$A$5:$A$238,0)) -> Mettupalayam | C45: =INDEX('AC Estimate'!$C$5:$C$238,MATCH($A45,'AC Estimate'!$A$5:$A$238,0)) -> Coimbatore | D45: =INDEX('AC Estimate'!$I$5:$I$238,MATCH($A45,'AC Estimate'!$A$5:$A$238,0)) -> 50 | E45: =INDEX('AC Estimate'!$J$5:$J$238,MATCH($A45,'AC Estimate'!$A$5:$A$238,0)) -> 0.24 | F45: =INDEX('AC Estimate'!$K$5:$K$238,MATCH($A45,'AC Estimate'!$A$5:$A$238,0)) -> 0.32 | G45: =INDEX('AC Estimate'!$L$5:$L$238,MATCH($A45,'AC Estimate'!$A$5:$A$238,0)) -> 0 | H45: =INDEX('AC Estimate'!$M$5:$M$238,MATCH($A45,'AC Estimate'!$A$5:$A$238,0)) -> 0.12 | I45: =INDEX('AC Estimate'!$N$5:$N$238,MATCH($A45,'AC Estimate'!$A$5:$A$238,0)) -> 0.32 | J45: =INDEX('AC Estimate'!$P$5:$P$238,MATCH($A45,'AC Estimate'!$A$5:$A$238,0)) -> DMK+ | K45: =INDEX('AC Estimate'!$AK$5:$AK$238,MATCH($A45,'AC Estimate'!$A$5:$A$238,0)) -> DMK+ | L45: =INDEX('AC Estimate'!$AM$5:$AM$238,MATCH($A45,'AC Estimate'!$A$5:$A$238,0)) -> 0.32006112 | M45: =INDEX('AC Estimate'!$Q$5:$Q$238,MATCH($A45,'AC Estimate'!$A$5:$A$238,0)) -> TVK | N45: =INDEX('AC Estimate'!$R$5:$R$238,MATCH($A45,'AC Estimate'!$A$5:$A$238,0)) -> TVK | O45: =INDEX('AC Estimate'!$AL$5:$AL$238,MATCH($A45,'AC Estimate'!$A$5:$A$238,0)) -> No
A46: 116 | B46: =INDEX('AC Estimate'!$B$5:$B$238,MATCH($A46,'AC Estimate'!$A$5:$A$238,0)) -> Sulur | C46: =INDEX('AC Estimate'!$C$5:$C$238,MATCH($A46,'AC Estimate'!$A$5:$A$238,0)) -> Coimbatore | D46: =INDEX('AC Estimate'!$I$5:$I$238,MATCH($A46,'AC Estimate'!$A$5:$A$238,0)) -> 59 | E46: =INDEX('AC Estimate'!$J$5:$J$238,MATCH($A46,'AC Estimate'!$A$5:$A$238,0)) -> 0.27118644 | F46: =INDEX('AC Estimate'!$K$5:$K$238,MATCH($A46,'AC Estimate'!$A$5:$A$238,0)) -> 0.28813559 | G46: =INDEX('AC Estimate'!$L$5:$L$238,MATCH($A46,'AC Estimate'!$A$5:$A$238,0)) -> 0.016949153 | H46: =INDEX('AC Estimate'!$M$5:$M$238,MATCH($A46,'AC Estimate'!$A$5:$A$238,0)) -> 0.050847458 | I46: =INDEX('AC Estimate'!$N$5:$N$238,MATCH($A46,'AC Estimate'!$A$5:$A$238,0)) -> 0.37288136 | J46: =INDEX('AC Estimate'!$P$5:$P$238,MATCH($A46,'AC Estimate'!$A$5:$A$238,0)) -> TVK | K46: =INDEX('AC Estimate'!$AK$5:$AK$238,MATCH($A46,'AC Estimate'!$A$5:$A$238,0)) -> TVK | L46: =INDEX('AC Estimate'!$AM$5:$AM$238,MATCH($A46,'AC Estimate'!$A$5:$A$238,0)) -> 0.51368375 | M46: =INDEX('AC Estimate'!$Q$5:$Q$238,MATCH($A46,'AC Estimate'!$A$5:$A$238,0)) -> TVK | N46: =INDEX('AC Estimate'!$R$5:$R$238,MATCH($A46,'AC Estimate'!$A$5:$A$238,0)) -> TVK | O46: =INDEX('AC Estimate'!$AL$5:$AL$238,MATCH($A46,'AC Estimate'!$A$5:$A$238,0)) -> Yes
A47: 117 | B47: =INDEX('AC Estimate'!$B$5:$B$238,MATCH($A47,'AC Estimate'!$A$5:$A$238,0)) -> Kavundampalayam | C47: =INDEX('AC Estimate'!$C$5:$C$238,MATCH($A47,'AC Estimate'!$A$5:$A$238,0)) -> Coimbatore | D47: =INDEX('AC Estimate'!$I$5:$I$238,MATCH($A47,'AC Estimate'!$A$5:$A$238,0)) -> 83 | E47: =INDEX('AC Estimate'!$J$5:$J$238,MATCH($A47,'AC Estimate'!$A$5:$A$238,0)) -> 0.30120482 | F47: =INDEX('AC Estimate'!$K$5:$K$238,MATCH($A47,'AC Estimate'!$A$5:$A$238,0)) -> 0.24096386 | G47: =INDEX('AC Estimate'!$L$5:$L$238,MATCH($A47,'AC Estimate'!$A$5:$A$238,0)) -> 0 | H47: =INDEX('AC Estimate'!$M$5:$M$238,MATCH($A47,'AC Estimate'!$A$5:$A$238,0)) -> 0.048192771 | I47: =INDEX('AC Estimate'!$N$5:$N$238,MATCH($A47,'AC Estimate'!$A$5:$A$238,0)) -> 0.40963855 | J47: =INDEX('AC Estimate'!$P$5:$P$238,MATCH($A47,'AC Estimate'!$A$5:$A$238,0)) -> TVK | K47: =INDEX('AC Estimate'!$AK$5:$AK$238,MATCH($A47,'AC Estimate'!$A$5:$A$238,0)) -> TVK | L47: =INDEX('AC Estimate'!$AM$5:$AM$238,MATCH($A47,'AC Estimate'!$A$5:$A$238,0)) -> 0.6660525 | M47: =INDEX('AC Estimate'!$Q$5:$Q$238,MATCH($A47,'AC Estimate'!$A$5:$A$238,0)) -> TVK | N47: =INDEX('AC Estimate'!$R$5:$R$238,MATCH($A47,'AC Estimate'!$A$5:$A$238,0)) -> TVK | O47: =INDEX('AC Estimate'!$AL$5:$AL$238,MATCH($A47,'AC Estimate'!$A$5:$A$238,0)) -> Yes
A48: 118 | B48: =INDEX('AC Estimate'!$B$5:$B$238,MATCH($A48,'AC Estimate'!$A$5:$A$238,0)) -> Coimbatore (North) | C48: =INDEX('AC Estimate'!$C$5:$C$238,MATCH($A48,'AC Estimate'!$A$5:$A$238,0)) -> Coimbatore | D48: =INDEX('AC Estimate'!$I$5:$I$238,MATCH($A48,'AC Estimate'!$A$5:$A$238,0)) -> 89 | E48: =INDEX('AC Estimate'!$J$5:$J$238,MATCH($A48,'AC Estimate'!$A$5:$A$238,0)) -> 0.28089888 | F48: =INDEX('AC Estimate'!$K$5:$K$238,MATCH($A48,'AC Estimate'!$A$5:$A$238,0)) -> 0.17977528 | G48: =INDEX('AC Estimate'!$L$5:$L$238,MATCH($A48,'AC Estimate'!$A$5:$A$238,0)) -> 0.011235955 | H48: =INDEX('AC Estimate'!$M$5:$M$238,MATCH($A48,'AC Estimate'!$A$5:$A$238,0)) -> 0.1011236 | I48: =INDEX('AC Estimate'!$N$5:$N$238,MATCH($A48,'AC Estimate'!$A$5:$A$238,0)) -> 0.42696629 | J48: =INDEX('AC Estimate'!$P$5:$P$238,MATCH($A48,'AC Estimate'!$A$5:$A$238,0)) -> TVK | K48: =INDEX('AC Estimate'!$AK$5:$AK$238,MATCH($A48,'AC Estimate'!$A$5:$A$238,0)) -> TVK | L48: =INDEX('AC Estimate'!$AM$5:$AM$238,MATCH($A48,'AC Estimate'!$A$5:$A$238,0)) -> 0.69853921 | M48: =INDEX('AC Estimate'!$Q$5:$Q$238,MATCH($A48,'AC Estimate'!$A$5:$A$238,0)) -> TVK | N48: =INDEX('AC Estimate'!$R$5:$R$238,MATCH($A48,'AC Estimate'!$A$5:$A$238,0)) -> TVK | O48: =INDEX('AC Estimate'!$AL$5:$AL$238,MATCH($A48,'AC Estimate'!$A$5:$A$238,0)) -> Yes
A49: 119 | B49: =INDEX('AC Estimate'!$B$5:$B$238,MATCH($A49,'AC Estimate'!$A$5:$A$238,0)) -> Thondamuthur | C49: =INDEX('AC Estimate'!$C$5:$C$238,MATCH($A49,'AC Estimate'!$A$5:$A$238,0)) -> Coimbatore | D49: =INDEX('AC Estimate'!$I$5:$I$238,MATCH($A49,'AC Estimate'!$A$5:$A$238,0)) -> 57 | E49: =INDEX('AC Estimate'!$J$5:$J$238,MATCH($A49,'AC Estimate'!$A$5:$A$238,0)) -> 0.24561404 | F49: =INDEX('AC Estimate'!$K$5:$K$238,MATCH($A49,'AC Estimate'!$A$5:$A$238,0)) -> 0.28070175 | G49: =INDEX('AC Estimate'!$L$5:$L$238,MATCH($A49,'AC Estimate'!$A$5:$A$238,0)) -> 0 | H49: =INDEX('AC Estimate'!$M$5:$M$238,MATCH($A49,'AC Estimate'!$A$5:$A$238,0)) -> 0.052631579 | I49: =INDEX('AC Estimate'!$N$5:$N$238,MATCH($A49,'AC Estimate'!$A$5:$A$238,0)) -> 0.42105263 | J49: =INDEX('AC Estimate'!$P$5:$P$238,MATCH($A49,'AC Estimate'!$A$5:$A$238,0)) -> TVK | K49: =INDEX('AC Estimate'!$AK$5:$AK$238,MATCH($A49,'AC Estimate'!$A$5:$A$238,0)) -> TVK | L49: =INDEX('AC Estimate'!$AM$5:$AM$238,MATCH($A49,'AC Estimate'!$A$5:$A$238,0)) -> 0.50982824 | M49: =INDEX('AC Estimate'!$Q$5:$Q$238,MATCH($A49,'AC Estimate'!$A$5:$A$238,0)) -> AIADMK | N49: =INDEX('AC Estimate'!$R$5:$R$238,MATCH($A49,'AC Estimate'!$A$5:$A$238,0)) -> AIADMK+ | O49: =INDEX('AC Estimate'!$AL$5:$AL$238,MATCH($A49,'AC Estimate'!$A$5:$A$238,0)) -> No
A50: 120 | B50: =INDEX('AC Estimate'!$B$5:$B$238,MATCH($A50,'AC Estimate'!$A$5:$A$238,0)) -> Coimbatore (South) | C50: =INDEX('AC Estimate'!$C$5:$C$238,MATCH($A50,'AC Estimate'!$A$5:$A$238,0)) -> Coimbatore | D50: =INDEX('AC Estimate'!$I$5:$I$238,MATCH($A50,'AC Estimate'!$A$5:$A$238,0)) -> 73 | E50: =INDEX('AC Estimate'!$J$5:$J$238,MATCH($A50,'AC Estimate'!$A$5:$A$238,0)) -> 0.24657534 | F50: =INDEX('AC Estimate'!$K$5:$K$238,MATCH($A50,'AC Estimate'!$A$5:$A$238,0)) -> 0.39726027 | G50: =INDEX('AC Estimate'!$L$5:$L$238,MATCH($A50,'AC Estimate'!$A$5:$A$238,0)) -> 0 | H50: =INDEX('AC Estimate'!$M$5:$M$238,MATCH($A50,'AC Estimate'!$A$5:$A$238,0)) -> 0.054794521 | I50: =INDEX('AC Estimate'!$N$5:$N$238,MATCH($A50,'AC Estimate'!$A$5:$A$238,0)) -> 0.30136986 | J50: =INDEX('AC Estimate'!$P$5:$P$238,MATCH($A50,'AC Estimate'!$A$5:$A$238,0)) -> DMK+ | K50: =INDEX('AC Estimate'!$AK$5:$AK$238,MATCH($A50,'AC Estimate'!$A$5:$A$238,0)) -> TVK | L50: =INDEX('AC Estimate'!$AM$5:$AM$238,MATCH($A50,'AC Estimate'!$A$5:$A$238,0)) -> 0.57372957 | M50: =INDEX('AC Estimate'!$Q$5:$Q$238,MATCH($A50,'AC Estimate'!$A$5:$A$238,0)) -> DMK | N50: =INDEX('AC Estimate'!$R$5:$R$238,MATCH($A50,'AC Estimate'!$A$5:$A$238,0)) -> DMK+ | O50: =INDEX('AC Estimate'!$AL$5:$AL$238,MATCH($A50,'AC Estimate'!$A$5:$A$238,0)) -> No
A51: 121 | B51: =INDEX('AC Estimate'!$B$5:$B$238,MATCH($A51,'AC Estimate'!$A$5:$A$238,0)) -> Singanallur | C51: =INDEX('AC Estimate'!$C$5:$C$238,MATCH($A51,'AC Estimate'!$A$5:$A$238,0)) -> Coimbatore | D51: =INDEX('AC Estimate'!$I$5:$I$238,MATCH($A51,'AC Estimate'!$A$5:$A$238,0)) -> 75 | E51: =INDEX('AC Estimate'!$J$5:$J$238,MATCH($A51,'AC Estimate'!$A$5:$A$238,0)) -> 0.29333333 | F51: =INDEX('AC Estimate'!$K$5:$K$238,MATCH($A51,'AC Estimate'!$A$5:$A$238,0)) -> 0.25333333 | G51: =INDEX('AC Estimate'!$L$5:$L$238,MATCH($A51,'AC Estimate'!$A$5:$A$238,0)) -> 0.013333333 | H51: =INDEX('AC Estimate'!$M$5:$M$238,MATCH($A51,'AC Estimate'!$A$5:$A$238,0)) -> 0.026666667 | I51: =INDEX('AC Estimate'!$N$5:$N$238,MATCH($A51,'AC Estimate'!$A$5:$A$238,0)) -> 0.41333333 | J51: =INDEX('AC Estimate'!$P$5:$P$238,MATCH($A51,'AC Estimate'!$A$5:$A$238,0)) -> TVK | K51: =INDEX('AC Estimate'!$AK$5:$AK$238,MATCH($A51,'AC Estimate'!$A$5:$A$238,0)) -> TVK | L51: =INDEX('AC Estimate'!$AM$5:$AM$238,MATCH($A51,'AC Estimate'!$A$5:$A$238,0)) -> 0.62711745 | M51: =INDEX('AC Estimate'!$Q$5:$Q$238,MATCH($A51,'AC Estimate'!$A$5:$A$238,0)) -> TVK | N51: =INDEX('AC Estimate'!$R$5:$R$238,MATCH($A51,'AC Estimate'!$A$5:$A$238,0)) -> TVK | O51: =INDEX('AC Estimate'!$AL$5:$AL$238,MATCH($A51,'AC Estimate'!$A$5:$A$238,0)) -> Yes
A52: 122 | B52: =INDEX('AC Estimate'!$B$5:$B$238,MATCH($A52,'AC Estimate'!$A$5:$A$238,0)) -> Kinathukadavu | C52: =INDEX('AC Estimate'!$C$5:$C$238,MATCH($A52,'AC Estimate'!$A$5:$A$238,0)) -> Coimbatore | D52: =INDEX('AC Estimate'!$I$5:$I$238,MATCH($A52,'AC Estimate'!$A$5:$A$238,0)) -> 59 | E52: =INDEX('AC Estimate'!$J$5:$J$238,MATCH($A52,'AC Estimate'!$A$5:$A$238,0)) -> 0.25423729 | F52: =INDEX('AC Estimate'!$K$5:$K$238,MATCH($A52,'AC Estimate'!$A$5:$A$238,0)) -> 0.38983051 | G52: =INDEX('AC Estimate'!$L$5:$L$238,MATCH($A52,'AC Estimate'!$A$5:$A$238,0)) -> 0 | H52: =INDEX('AC Estimate'!$M$5:$M$238,MATCH($A52,'AC Estimate'!$A$5:$A$238,0)) -> 0.050847458 | I52: =INDEX('AC Estimate'!$N$5:$N$238,MATCH($A52,'AC Estimate'!$A$5:$A$238,0)) -> 0.30508475 | J52: =INDEX('AC Estimate'!$P$5:$P$238,MATCH($A52,'AC Estimate'!$A$5:$A$238,0)) -> DMK+ | K52: =INDEX('AC Estimate'!$AK$5:$AK$238,MATCH($A52,'AC Estimate'!$A$5:$A$238,0)) -> DMK+ | L52: =INDEX('AC Estimate'!$AM$5:$AM$238,MATCH($A52,'AC Estimate'!$A$5:$A$238,0)) -> 0.29646661 | M52: =INDEX('AC Estimate'!$Q$5:$Q$238,MATCH($A52,'AC Estimate'!$A$5:$A$238,0)) -> TVK | N52: =INDEX('AC Estimate'!$R$5:$R$238,MATCH($A52,'AC Estimate'!$A$5:$A$238,0)) -> TVK | O52: =INDEX('AC Estimate'!$AL$5:$AL$238,MATCH($A52,'AC Estimate'!$A$5:$A$238,0)) -> No
A53: 123 | B53: =INDEX('AC Estimate'!$B$5:$B$238,MATCH($A53,'AC Estimate'!$A$5:$A$238,0)) -> Pollachi | C53: =INDEX('AC Estimate'!$C$5:$C$238,MATCH($A53,'AC Estimate'!$A$5:$A$238,0)) -> Coimbatore | D53: =INDEX('AC Estimate'!$I$5:$I$238,MATCH($A53,'AC Estimate'!$A$5:$A$238,0)) -> 51 | E53: =INDEX('AC Estimate'!$J$5:$J$238,MATCH($A53,'AC Estimate'!$A$5:$A$238,0)) -> 0.35294118 | F53: =INDEX('AC Estimate'!$K$5:$K$238,MATCH($A53,'AC Estimate'!$A$5:$A$238,0)) -> 0.1372549 | G53: =INDEX('AC Estimate'!$L$5:$L$238,MATCH($A53,'AC Estimate'!$A$5:$A$238,0)) -> 0 | H53: =INDEX('AC Estimate'!$M$5:$M$238,MATCH($A53,'AC Estimate'!$A$5:$A$238,0)) -> 0.039215686 | I53: =INDEX('AC Estimate'!$N$5:$N$238,MATCH($A53,'AC Estimate'!$A$5:$A$238,0)) -> 0.47058824 | J53: =INDEX('AC Estimate'!$P$5:$P$238,MATCH($A53,'AC Estimate'!$A$5:$A$238,0)) -> TVK | K53: =INDEX('AC Estimate'!$AK$5:$AK$238,MATCH($A53,'AC Estimate'!$A$5:$A$238,0)) -> AIADMK+ | L53: =INDEX('AC Estimate'!$AM$5:$AM$238,MATCH($A53,'AC Estimate'!$A$5:$A$238,0)) -> 0.2995515 | M53: =INDEX('AC Estimate'!$Q$5:$Q$238,MATCH($A53,'AC Estimate'!$A$5:$A$238,0)) -> DMK | N53: =INDEX('AC Estimate'!$R$5:$R$238,MATCH($A53,'AC Estimate'!$A$5:$A$238,0)) -> DMK+ | O53: =INDEX('AC Estimate'!$AL$5:$AL$238,MATCH($A53,'AC Estimate'!$A$5:$A$238,0)) -> No
...

Sheet AC Estimate
A1: Tamil Nadu 2026 — AC-wise estimate (Saket) with district and actual 2026 result
A2: Survey vote counts and "Winner (estimate)" are from SAKET_TN.xlsx, unchanged (blue). AC number and district: Wikipedia, "List of constituencies of the Tamil Nadu Legislative Assembly", grouped as in the district-wise results of "2026 Tamil Nadu Legislative Assembly election" (ECI). Actual 2026 winner: ECI result (4 May 2026) as listed by IndiaVotes; party totals match ECI.
A4: AC No | B4: AC | C4: District (ECI 2026) | D4: AIDMK+BJP+PMK+AMMK | E4: DMK+INC+VCK | F4: NOTA | G4: NTK | H4: TVK | I4: Total | J4: AIDMK+BJP+PMK+AMMK % | K4: DMK+INC+VCK % | L4: NOTA % | M4: NTK % | N4: TVK % | O4: Winner (estimate) | P4: Estimate alliance | Q4: Actual 2026 winner party (ECI) | R4: Actual 2026 alliance | S4: Match? | T4: Note | U4: Dist AIADMK+ % | V4: Dist DMK+ % | W4: Dist NOTA % | X4: Dist NTK % | Y4: Dist TVK % | Z4: ln(n) | AA4: Score AIADMK+ | AB4: Score DMK+ | AC4: Score TVK | AD4: P(win) TVK | AE4: Model call (statewide fit) | AF4: Calibrated match? | AG4: Changed vs Saket? | AH4: Survey leader | AI4: P(win) AIADMK+ | AJ4: P(win) DMK+ | AK4: Final estimate (district-calibrated) | AL4: Final match? | AM4: P(win) of final call | AN4: Changed vs Saket?
A5: 1 | B5: Gummidipoondi | C5: Thiruvallur | D5: 9 | E5: 12 | G5: 2 | H5: 22 | I5: =SUM(D5:H5) -> 45 | J5: =IF($I5=0,0,D5/$I5) -> 0.2 | K5: =IF($I5=0,0,E5/$I5) -> 0.26666667 | L5: =IF($I5=0,0,F5/$I5) -> 0 | M5: =IF($I5=0,0,G5/$I5) -> 0.044444444 | N5: =IF($I5=0,0,H5/$I5) -> 0.48888889 | O5: TVK | P5: =IF(O5="TVK","TVK",IF(O5="DMK","DMK+",IF(O5="ADMK","AIADMK+",""))) -> TVK | Q5: TVK | R5: TVK | S5: =IF(P5=R5,"Yes","No") -> Yes | U5: =IFERROR(SUMIFS($D$5:$D$238,$C$5:$C$238,$C5)/SUMIFS($I$5:$I$238,$C$5:$C$238,$C5),0) -> 0.18415842 | V5: =IFERROR(SUMIFS($E$5:$E$238,$C$5:$C$238,$C5)/SUMIFS($I$5:$I$238,$C$5:$C$238,$C5),0) -> 0.32475248 | W5: =IFERROR(SUMIFS($F$5:$F$238,$C$5:$C$238,$C5)/SUMIFS($I$5:$I$238,$C$5:$C$238,$C5),0) -> 0.011881188 | X5: =IFERROR(SUMIFS($G$5:$G$238,$C$5:$C$238,$C5)/SUMIFS($I$5:$I$238,$C$5:$C$238,$C5),0) -> 0.057425743 | Y5: =IFERROR(SUMIFS($H$5:$H$238,$C$5:$C$238,$C5)/SUMIFS($I$5:$I$238,$C$5:$C$238,$C5),0) -> 0.42178218 | Z5: =LN(MAX(I5,1)) -> 3.8066625 | AA5: =Calibration!$M$35+Calibration!$N$35+SUMPRODUCT(Calibration!$B$35:$F$35,J5:N5)+SUMPRODUCT(Calibration!$G$35:$K$35,U5:Y5)+Calibration!$L$35*Z5 -> -0.026400142 | AB5: =Calibration!$M$36+Calibration!$N$36+SUMPRODUCT(Calibration!$B$36:$F$36,J5:N5)+SUMPRODUCT(Calibration!$G$36:$K$36,U5:Y5)+Calibration!$L$36*Z5 -> 0.28772511 | AC5: =Calibration!$M$37+Calibration!$N$37+SUMPRODUCT(Calibration!$B$37:$F$37,J5:N5)+SUMPRODUCT(Calibration!$G$37:$K$37,U5:Y5)+Calibration!$L$37*Z5 -> 0.56367585 | AD5: =EXP(AC5)/(EXP(AA5)+EXP(AB5)+EXP(AC5)) -> 0.43231363 | AE5: =IF(AC5=MAX(AA5:AC5),"TVK",IF(AB5=MAX(AA5:AC5),"DMK+","AIADMK+")) -> TVK | AF5: =IF(AE5=R5,"Yes","No") -> Yes | AG5: =IF(AE5=P5,"No","Yes") -> No | AH5: =IF(H5=MAX(D5,E5,H5),"TVK",IF(E5=MAX(D5,E5,H5),"DMK+","AIADMK+")) -> TVK | AI5: =EXP(AA5)/(EXP(AA5)+EXP(AB5)+EXP(AC5)) -> 0.23962503 | AJ5: =EXP(AB5)/(EXP(AA5)+EXP(AB5)+EXP(AC5)) -> 0.32806133 | AK5: AIADMK+ | AL5: =IF(AK5=R5,"Yes","No") -> No | AM5: =IF(AK5="TVK",AD5,IF(AK5="DMK+",AJ5,AI5)) -> 0.23962503 | AN5: =IF(AK5=P5,"No","Yes") -> Yes
A6: 2 | B6: Ponneri | C6: Thiruvallur | D6: 14 | E6: 18 | F6: 1 | G6: 4 | H6: 41 | I6: =SUM(D6:H6) -> 78 | J6: =IF($I6=0,0,D6/$I6) -> 0.17948718 | K6: =IF($I6=0,0,E6/$I6) -> 0.23076923 | L6: =IF($I6=0,0,F6/$I6) -> 0.012820513 | M6: =IF($I6=0,0,G6/$I6) -> 0.051282051 | N6: =IF($I6=0,0,H6/$I6) -> 0.52564103 | O6: TVK | P6: =IF(O6="TVK","TVK",IF(O6="DMK","DMK+",IF(O6="ADMK","AIADMK+",""))) -> TVK | Q6: TVK | R6: TVK | S6: =IF(P6=R6,"Yes","No") -> Yes | U6: =IFERROR(SUMIFS($D$5:$D$238,$C$5:$C$238,$C6)/SUMIFS($I$5:$I$238,$C$5:$C$238,$C6),0) -> 0.18415842 | V6: =IFERROR(SUMIFS($E$5:$E$238,$C$5:$C$238,$C6)/SUMIFS($I$5:$I$238,$C$5:$C$238,$C6),0) -> 0.32475248 | W6: =IFERROR(SUMIFS($F$5:$F$238,$C$5:$C$238,$C6)/SUMIFS($I$5:$I$238,$C$5:$C$238,$C6),0) -> 0.011881188 | X6: =IFERROR(SUMIFS($G$5:$G$238,$C$5:$C$238,$C6)/SUMIFS($I$5:$I$238,$C$5:$C$238,$C6),0) -> 0.057425743 | Y6: =IFERROR(SUMIFS($H$5:$H$238,$C$5:$C$238,$C6)/SUMIFS($I$5:$I$238,$C$5:$C$238,$C6),0) -> 0.42178218 | Z6: =LN(MAX(I6,1)) -> 4.3567088 | AA6: =Calibration!$M$35+Calibration!$N$35+SUMPRODUCT(Calibration!$B$35:$F$35,J6:N6)+SUMPRODUCT(Calibration!$G$35:$K$35,U6:Y6)+Calibration!$L$35*Z6 -> -0.31142324 | AB6: =Calibration!$M$36+Calibration!$N$36+SUMPRODUCT(Calibration!$B$36:$F$36,J6:N6)+SUMPRODUCT(Calibration!$G$36:$K$36,U6:Y6)+Calibration!$L$36*Z6 -> -0.086220274 | AC6: =Calibration!$M$37+Calibration!$N$37+SUMPRODUCT(Calibration!$B$37:$F$37,J6:N6)+SUMPRODUCT(Calibration!$G$37:$K$37,U6:Y6)+Calibration!$L$37*Z6 -> 1.2226444 | AD6: =EXP(AC6)/(EXP(AA6)+EXP(AB6)+EXP(AC6)) -> 0.67304568 | AE6: =IF(AC6=MAX(AA6:AC6),"TVK",IF(AB6=MAX(AA6:AC6),"DMK+","AIADMK+")) -> TVK | AF6: =IF(AE6=R6,"Yes","No") -> Yes | AG6: =IF(AE6=P6,"No","Yes") -> No | AH6: =IF(H6=MAX(D6,E6,H6),"TVK",IF(E6=MAX(D6,E6,H6),"DMK+","AIADMK+")) -> TVK | AI6: =EXP(AA6)/(EXP(AA6)+EXP(AB6)+EXP(AC6)) -> 0.14514679 | AJ6: =EXP(AB6)/(EXP(AA6)+EXP(AB6)+EXP(AC6)) -> 0.18180752 | AK6: TVK | AL6: =IF(AK6=R6,"Yes","No") -> Yes | AM6: =IF(AK6="TVK",AD6,IF(AK6="DMK+",AJ6,AI6)) -> 0.67304568 | AN6: =IF(AK6=P6,"No","Yes") -> No
A7: 3 | B7: Tiruttani | C7: Thiruvallur | D7: 16 | E7: 15 | F7: 1 | G7: 2 | H7: 25 | I7: =SUM(D7:H7) -> 59 | J7: =IF($I7=0,0,D7/$I7) -> 0.27118644 | K7: =IF($I7=0,0,E7/$I7) -> 0.25423729 | L7: =IF($I7=0,0,F7/$I7) -> 0.016949153 | M7: =IF($I7=0,0,G7/$I7) -> 0.033898305 | N7: =IF($I7=0,0,H7/$I7) -> 0.42372881 | O7: TVK | P7: =IF(O7="TVK","TVK",IF(O7="DMK","DMK+",IF(O7="ADMK","AIADMK+",""))) -> TVK | Q7: AIADMK | R7: AIADMK+ | S7: =IF(P7=R7,"Yes","No") -> No | U7: =IFERROR(SUMIFS($D$5:$D$238,$C$5:$C$238,$C7)/SUMIFS($I$5:$I$238,$C$5:$C$238,$C7),0) -> 0.18415842 | V7: =IFERROR(SUMIFS($E$5:$E$238,$C$5:$C$238,$C7)/SUMIFS($I$5:$I$238,$C$5:$C$238,$C7),0) -> 0.32475248 | W7: =IFERROR(SUMIFS($F$5:$F$238,$C$5:$C$238,$C7)/SUMIFS($I$5:$I$238,$C$5:$C$238,$C7),0) -> 0.011881188 | X7: =IFERROR(SUMIFS($G$5:$G$238,$C$5:$C$238,$C7)/SUMIFS($I$5:$I$238,$C$5:$C$238,$C7),0) -> 0.057425743 | Y7: =IFERROR(SUMIFS($H$5:$H$238,$C$5:$C$238,$C7)/SUMIFS($I$5:$I$238,$C$5:$C$238,$C7),0) -> 0.42178218 | Z7: =LN(MAX(I7,1)) -> 4.0775374 | AA7: =Calibration!$M$35+Calibration!$N$35+SUMPRODUCT(Calibration!$B$35:$F$35,J7:N7)+SUMPRODUCT(Calibration!$G$35:$K$35,U7:Y7)+Calibration!$L$35*Z7 -> -0.082397522 | AB7: =Calibration!$M$36+Calibration!$N$36+SUMPRODUCT(Calibration!$B$36:$F$36,J7:N7)+SUMPRODUCT(Calibration!$G$36:$K$36,U7:Y7)+Calibration!$L$36*Z7 -> 0.067574116 | AC7: =Calibration!$M$37+Calibration!$N$37+SUMPRODUCT(Calibration!$B$37:$F$37,J7:N7)+SUMPRODUCT(Calibration!$G$37:$K$37,U7:Y7)+Calibration!$L$37*Z7 -> 0.83982416 | AD7: =EXP(AC7)/(EXP(AA7)+EXP(AB7)+EXP(AC7)) -> 0.53774801 | AE7: =IF(AC7=MAX(AA7:AC7),"TVK",IF(AB7=MAX(AA7:AC7),"DMK+","AIADMK+")) -> TVK | AF7: =IF(AE7=R7,"Yes","No") -> No | AG7: =IF(AE7=P7,"No","Yes") -> No | AH7: =IF(H7=MAX(D7,E7,H7),"TVK",IF(E7=MAX(D7,E7,H7),"DMK+","AIADMK+")) -> TVK | AI7: =EXP(AA7)/(EXP(AA7)+EXP(AB7)+EXP(AC7)) -> 0.21382724 | AJ7: =EXP(AB7)/(EXP(AA7)+EXP(AB7)+EXP(AC7)) -> 0.24842476 | AK7: TVK | AL7: =IF(AK7=R7,"Yes","No") -> No | AM7: =IF(AK7="TVK",AD7,IF(AK7="DMK+",AJ7,AI7)) -> 0.53774801 | AN7: =IF(AK7=P7,"No","Yes") -> No
