Workbook

Sheet Summary
A1: TN 2026 Exit Poll Analysis — data export
A2: Export of the "TN 2026 Exit Poll Analysis" dashboard. Blue = counts from the survey file; black = formulas.
A4: Headline
A5: Votes analysed | B5: ='Statewide Votes'!G5 -> 31316
A6: With district or AC | B6: ='Statewide Votes'!G6 -> 11449
A7: Vote only (no location) | B7: ='Statewide Votes'!G7 -> 19867
A8: Constituencies covered | B8: =COUNTA('AC Results'!$A$5:$A$238) -> 234
A9: Firm calls (Strong + Lean) | B9: =COUNTIF('AC Results'!$V$5:$V$238,"Strong")+COUNTIF('AC Results'!$V$5:$V$238,"Lean") -> 159
A11: Vote share
A12: Respondent group | B12: TVK | C12: AIADMK+ | D12: DMK+ | E12: NTK | F12: NOTA
A13: All responses | B13: ='Statewide Votes'!H5 -> 0.34780943 | C13: ='Statewide Votes'!I5 -> 0.28279474 | D13: ='Statewide Votes'!J5 -> 0.29205518 | E13: ='Statewide Votes'!K5 -> 0.069389449 | F13: ='Statewide Votes'!L5 -> 0.0079512071
A14: With district or AC | B14: ='Statewide Votes'!H6 -> 0.39243602 | C14: ='Statewide Votes'!I6 -> 0.27539523 | D14: ='Statewide Votes'!J6 -> 0.24770722 | E14: ='Statewide Votes'!K6 -> 0.078172766 | F14: ='Statewide Votes'!L6 -> 0.0062887588
A15: Vote only (no location) | B15: ='Statewide Votes'!H7 -> 0.32209191 | C15: ='Statewide Votes'!I7 -> 0.28705894 | D15: ='Statewide Votes'!J7 -> 0.31761212 | E15: ='Statewide Votes'!K7 -> 0.06432778 | F15: ='Statewide Votes'!L7 -> 0.0089092465
A17: Projected seats (234)
A18: Party | B18: Seats | C18: Strong | D18: Lean | E18: Toss-up | F18: Low sample
A19: TVK | B19: =COUNTIF('AC Results'!$S$5:$S$238,A19) -> 115 | C19: =COUNTIFS('AC Results'!$S$5:$S$238,$A19,'AC Results'!$V$5:$V$238,"Strong") -> 37 | D19: =COUNTIFS('AC Results'!$S$5:$S$238,$A19,'AC Results'!$V$5:$V$238,"Lean") -> 46 | E19: =COUNTIFS('AC Results'!$S$5:$S$238,$A19,'AC Results'!$V$5:$V$238,"Toss-up") -> 32 | F19: =COUNTIFS('AC Results'!$S$5:$S$238,$A19,'AC Results'!$V$5:$V$238,"Low sample") -> 0
A20: AIADMK+BJP+PMK+AMMK | B20: =COUNTIF('AC Results'!$S$5:$S$238,A20) -> 60 | C20: =COUNTIFS('AC Results'!$S$5:$S$238,$A20,'AC Results'!$V$5:$V$238,"Strong") -> 18 | D20: =COUNTIFS('AC Results'!$S$5:$S$238,$A20,'AC Results'!$V$5:$V$238,"Lean") -> 25 | E20: =COUNTIFS('AC Results'!$S$5:$S$238,$A20,'AC Results'!$V$5:$V$238,"Toss-up") -> 16 | F20: =COUNTIFS('AC Results'!$S$5:$S$238,$A20,'AC Results'!$V$5:$V$238,"Low sample") -> 1
A21: DMK+INC+VCK | B21: =COUNTIF('AC Results'!$S$5:$S$238,A21) -> 56 | C21: =COUNTIFS('AC Results'!$S$5:$S$238,$A21,'AC Results'!$V$5:$V$238,"Strong") -> 13 | D21: =COUNTIFS('AC Results'!$S$5:$S$238,$A21,'AC Results'!$V$5:$V$238,"Lean") -> 18 | E21: =COUNTIFS('AC Results'!$S$5:$S$238,$A21,'AC Results'!$V$5:$V$238,"Toss-up") -> 25 | F21: =COUNTIFS('AC Results'!$S$5:$S$238,$A21,'AC Results'!$V$5:$V$238,"Low sample") -> 0
A22: NTK | B22: =COUNTIF('AC Results'!$S$5:$S$238,A22) -> 3 | C22: =COUNTIFS('AC Results'!$S$5:$S$238,$A22,'AC Results'!$V$5:$V$238,"Strong") -> 1 | D22: =COUNTIFS('AC Results'!$S$5:$S$238,$A22,'AC Results'!$V$5:$V$238,"Lean") -> 1 | E22: =COUNTIFS('AC Results'!$S$5:$S$238,$A22,'AC Results'!$V$5:$V$238,"Toss-up") -> 1 | F22: =COUNTIFS('AC Results'!$S$5:$S$238,$A22,'AC Results'!$V$5:$V$238,"Low sample") -> 0
A23: Tie | B23: =COUNTIF('AC Results'!$S$5:$S$238,A23) -> 0 | C23: =COUNTIFS('AC Results'!$S$5:$S$238,$A23,'AC Results'!$V$5:$V$238,"Strong") -> 0 | D23: =COUNTIFS('AC Results'!$S$5:$S$238,$A23,'AC Results'!$V$5:$V$238,"Lean") -> 0 | E23: =COUNTIFS('AC Results'!$S$5:$S$238,$A23,'AC Results'!$V$5:$V$238,"Toss-up") -> 0 | F23: =COUNTIFS('AC Results'!$S$5:$S$238,$A23,'AC Results'!$V$5:$V$238,"Low sample") -> 0
A24: Total | B24: =SUM(B19:B23) -> 234 | C24: =SUM(C19:C23) -> 69 | D24: =SUM(D19:D23) -> 90 | E24: =SUM(E19:E23) -> 74 | F24: =SUM(F19:F23) -> 1
A25: Majority = 118. Seats use shares shifted to all 31,316 votes (uniform swing); see Statewide Votes.
A27: Districts led
A28: Party | B28: Districts
A29: TVK | B29: =COUNTIF('District Results'!$M$5:$M$42,A29) -> 22
A30: AIADMK+BJP+PMK+AMMK | B30: =COUNTIF('District Results'!$M$5:$M$42,A30) -> 8
A31: DMK+INC+VCK | B31: =COUNTIF('District Results'!$M$5:$M$42,A31) -> 8

Sheet Statewide Votes
A1: Statewide votes by respondent group
A2: Source: TN Election Poll 2026 file (7 forms), 31,316 responses with a party chosen, no rows removed. "Others" was already counted under DMK+INC+VCK in the file.
A4: Respondent group | B4: TVK votes | C4: AIADMK+ votes | D4: DMK+ votes | E4: NTK votes | F4: NOTA votes | G4: Total | H4: TVK share | I4: AIADMK+ share | J4: DMK+ share | K4: NTK share | L4: NOTA share
A5: All responses | B5: 10892 | C5: 8856 | D5: 9146 | E5: 2173 | F5: 249 | G5: =SUM(B5:F5) -> 31316 | H5: =IF($G5=0,0,B5/$G5) -> 0.34780943 | I5: =IF($G5=0,0,C5/$G5) -> 0.28279474 | J5: =IF($G5=0,0,D5/$G5) -> 0.29205518 | K5: =IF($G5=0,0,E5/$G5) -> 0.069389449 | L5: =IF($G5=0,0,F5/$G5) -> 0.0079512071
A6: With district or AC | B6: 4493 | C6: 3153 | D6: 2836 | E6: 895 | F6: 72 | G6: =SUM(B6:F6) -> 11449 | H6: =IF($G6=0,0,B6/$G6) -> 0.39243602 | I6: =IF($G6=0,0,C6/$G6) -> 0.27539523 | J6: =IF($G6=0,0,D6/$G6) -> 0.24770722 | K6: =IF($G6=0,0,E6/$G6) -> 0.078172766 | L6: =IF($G6=0,0,F6/$G6) -> 0.0062887588
A7: Vote only (no location) | B7: 6399 | C7: 5703 | D7: 6310 | E7: 1278 | F7: 177 | G7: =SUM(B7:F7) -> 19867 | H7: =IF($G7=0,0,B7/$G7) -> 0.32209191 | I7: =IF($G7=0,0,C7/$G7) -> 0.28705894 | J7: =IF($G7=0,0,D7/$G7) -> 0.31761212 | K7: =IF($G7=0,0,E7/$G7) -> 0.06432778 | L7: =IF($G7=0,0,F7/$G7) -> 0.0089092465
A9: Shift to all 31,316 votes (pts) | H9: =(H5-H6)*100 -> -4.4626594 | I9: =(I5-I6)*100 -> 0.73995065 | J9: =(J5-J6)*100 -> 4.4347956 | K9: =(K5-K6)*100 -> -0.87833167 | L9: =(L5-L6)*100 -> 0.16624482
A10: Shift = share among all votes minus share among votes with a location. It is added to every district and constituency share (uniform swing), so located results match the full sample level.

Sheet AC Results
A1: Constituency-wise winners — shares shifted to all 31,316 votes
A2: Raw = share of that AC's own responses. Adjusted = raw + statewide shift (floored at 0). Confidence: Tie if margin 0; Low sample if n<10; Strong if n≥30 and margin ≥10 pts; Lean if margin ≥5; else Toss-up.
A4: Constituency | B4: District | C4: TVK votes | D4: AIADMK+ votes | E4: DMK+ votes | F4: NTK votes | G4: NOTA votes | H4: Responses (n) | I4: TVK raw % | J4: AIADMK+ raw % | K4: DMK+ raw % | L4: NTK raw % | M4: NOTA raw % | N4: TVK adjusted % | O4: AIADMK+ adjusted % | P4: DMK+ adjusted % | Q4: NTK adjusted % | R4: NOTA adjusted % | S4: Winner | T4: Runner-up | U4: Margin (pts) | V4: Confidence | W4: Winner before shift | X4: Winner % | Y4: District (2026 ECI grouping)
A5: Ariyalur | B5: Ariyalur | C5: 18 | D5: 16 | E5: 9 | F5: 8 | G5: 0 | H5: =SUM(C5:G5) -> 51 | I5: =IF($H5=0,0,C5/$H5) -> 0.35294118 | J5: =IF($H5=0,0,D5/$H5) -> 0.31372549 | K5: =IF($H5=0,0,E5/$H5) -> 0.17647059 | L5: =IF($H5=0,0,F5/$H5) -> 0.15686275 | M5: =IF($H5=0,0,G5/$H5) -> 0 | N5: =MAX(0,I5+'Statewide Votes'!$H$9/100) -> 0.30831458 | O5: =MAX(0,J5+'Statewide Votes'!$I$9/100) -> 0.321125 | P5: =MAX(0,K5+'Statewide Votes'!$J$9/100) -> 0.22081854 | Q5: =MAX(0,L5+'Statewide Votes'!$K$9/100) -> 0.14807943 | R5: =MAX(0,M5+'Statewide Votes'!$L$9/100) -> 0.0016624482 | S5: =IF(U5=0,"Tie",INDEX({"TVK","AIADMK+BJP+PMK+AMMK","DMK+INC+VCK","NTK","NOTA"},MATCH(MAX(N5:R5),N5:R5,0))) -> AIADMK+BJP+PMK+AMMK | T5: =INDEX({"TVK","AIADMK+BJP+PMK+AMMK","DMK+INC+VCK","NTK","NOTA"},MATCH(LARGE(N5:R5,2),N5:R5,0)) -> TVK | U5: =ROUND((LARGE(N5:R5,1)-LARGE(N5:R5,2))*100,1) -> 1.3 | V5: =IF(U5=0,"Tie",IF(H5<10,"Low sample",IF(AND(H5>=30,U5>=10),"Strong",IF(U5>=5,"Lean","Toss-up")))) -> Toss-up | W5: =IF(LARGE(I5:M5,1)=LARGE(I5:M5,2),"Tie",INDEX({"TVK","AIADMK+BJP+PMK+AMMK","DMK+INC+VCK","NTK","NOTA"},MATCH(MAX(I5:M5),I5:M5,0))) -> TVK | X5: =MAX(N5:R5) -> 0.321125 | Y5: =IF(ISNUMBER(MATCH(A5,{"Maduravoyal","Ambattur","Madavaram","Thiruvottiyur","Sholinganallur","Alandur"},0)),"Chennai",B5) -> Ariyalur
A6: Jayankondam | B6: Ariyalur | C6: 14 | D6: 12 | E6: 5 | F6: 1 | G6: 0 | H6: =SUM(C6:G6) -> 32 | I6: =IF($H6=0,0,C6/$H6) -> 0.4375 | J6: =IF($H6=0,0,D6/$H6) -> 0.375 | K6: =IF($H6=0,0,E6/$H6) -> 0.15625 | L6: =IF($H6=0,0,F6/$H6) -> 0.03125 | M6: =IF($H6=0,0,G6/$H6) -> 0 | N6: =MAX(0,I6+'Statewide Votes'!$H$9/100) -> 0.39287341 | O6: =MAX(0,J6+'Statewide Votes'!$I$9/100) -> 0.38239951 | P6: =MAX(0,K6+'Statewide Votes'!$J$9/100) -> 0.20059796 | Q6: =MAX(0,L6+'Statewide Votes'!$K$9/100) -> 0.022466683 | R6: =MAX(0,M6+'Statewide Votes'!$L$9/100) -> 0.0016624482 | S6: =IF(U6=0,"Tie",INDEX({"TVK","AIADMK+BJP+PMK+AMMK","DMK+INC+VCK","NTK","NOTA"},MATCH(MAX(N6:R6),N6:R6,0))) -> TVK | T6: =INDEX({"TVK","AIADMK+BJP+PMK+AMMK","DMK+INC+VCK","NTK","NOTA"},MATCH(LARGE(N6:R6,2),N6:R6,0)) -> AIADMK+BJP+PMK+AMMK | U6: =ROUND((LARGE(N6:R6,1)-LARGE(N6:R6,2))*100,1) -> 1 | V6: =IF(U6=0,"Tie",IF(H6<10,"Low sample",IF(AND(H6>=30,U6>=10),"Strong",IF(U6>=5,"Lean","Toss-up")))) -> Toss-up | W6: =IF(LARGE(I6:M6,1)=LARGE(I6:M6,2),"Tie",INDEX({"TVK","AIADMK+BJP+PMK+AMMK","DMK+INC+VCK","NTK","NOTA"},MATCH(MAX(I6:M6),I6:M6,0))) -> TVK | X6: =MAX(N6:R6) -> 0.39287341 | Y6: =IF(ISNUMBER(MATCH(A6,{"Maduravoyal","Ambattur","Madavaram","Thiruvottiyur","Sholinganallur","Alandur"},0)),"Chennai",B6) -> Ariyalur
A7: Chengalpattu | B7: Chengalpattu | C7: 35 | D7: 13 | E7: 13 | F7: 5 | G7: 1 | H7: =SUM(C7:G7) -> 67 | I7: =IF($H7=0,0,C7/$H7) -> 0.52238806 | J7: =IF($H7=0,0,D7/$H7) -> 0.19402985 | K7: =IF($H7=0,0,E7/$H7) -> 0.19402985 | L7: =IF($H7=0,0,F7/$H7) -> 0.074626866 | M7: =IF($H7=0,0,G7/$H7) -> 0.014925373 | N7: =MAX(0,I7+'Statewide Votes'!$H$9/100) -> 0.47776147 | O7: =MAX(0,J7+'Statewide Votes'!$I$9/100) -> 0.20142936 | P7: =MAX(0,K7+'Statewide Votes'!$J$9/100) -> 0.23837781 | Q7: =MAX(0,L7+'Statewide Votes'!$K$9/100) -> 0.065843549 | R7: =MAX(0,M7+'Statewide Votes'!$L$9/100) -> 0.016587821 | S7: =IF(U7=0,"Tie",INDEX({"TVK","AIADMK+BJP+PMK+AMMK","DMK+INC+VCK","NTK","NOTA"},MATCH(MAX(N7:R7),N7:R7,0))) -> TVK | T7: =INDEX({"TVK","AIADMK+BJP+PMK+AMMK","DMK+INC+VCK","NTK","NOTA"},MATCH(LARGE(N7:R7,2),N7:R7,0)) -> DMK+INC+VCK | U7: =ROUND((LARGE(N7:R7,1)-LARGE(N7:R7,2))*100,1) -> 23.9 | V7: =IF(U7=0,"Tie",IF(H7<10,"Low sample",IF(AND(H7>=30,U7>=10),"Strong",IF(U7>=5,"Lean","Toss-up")))) -> Strong | W7: =IF(LARGE(I7:M7,1)=LARGE(I7:M7,2),"Tie",INDEX({"TVK","AIADMK+BJP+PMK+AMMK","DMK+INC+VCK","NTK","NOTA"},MATCH(MAX(I7:M7),I7:M7,0))) -> TVK | X7: =MAX(N7:R7) -> 0.47776147 | Y7: =IF(ISNUMBER(MATCH(A7,{"Maduravoyal","Ambattur","Madavaram","Thiruvottiyur","Sholinganallur","Alandur"},0)),"Chennai",B7) -> Chengalpattu
A8: Cheyyur | B8: Chengalpattu | C8: 6 | D8: 12 | E8: 3 | F8: 1 | G8: 0 | H8: =SUM(C8:G8) -> 22 | I8: =IF($H8=0,0,C8/$H8) -> 0.27272727 | J8: =IF($H8=0,0,D8/$H8) -> 0.54545455 | K8: =IF($H8=0,0,E8/$H8) -> 0.13636364 | L8: =IF($H8=0,0,F8/$H8) -> 0.045454545 | M8: =IF($H8=0,0,G8/$H8) -> 0 | N8: =MAX(0,I8+'Statewide Votes'!$H$9/100) -> 0.22810068 | O8: =MAX(0,J8+'Statewide Votes'!$I$9/100) -> 0.55285405 | P8: =MAX(0,K8+'Statewide Votes'!$J$9/100) -> 0.18071159 | Q8: =MAX(0,L8+'Statewide Votes'!$K$9/100) -> 0.036671229 | R8: =MAX(0,M8+'Statewide Votes'!$L$9/100) -> 0.0016624482 | S8: =IF(U8=0,"Tie",INDEX({"TVK","AIADMK+BJP+PMK+AMMK","DMK+INC+VCK","NTK","NOTA"},MATCH(MAX(N8:R8),N8:R8,0))) -> AIADMK+BJP+PMK+AMMK | T8: =INDEX({"TVK","AIADMK+BJP+PMK+AMMK","DMK+INC+VCK","NTK","NOTA"},MATCH(LARGE(N8:R8,2),N8:R8,0)) -> TVK | U8: =ROUND((LARGE(N8:R8,1)-LARGE(N8:R8,2))*100,1) -> 32.5 | V8: =IF(U8=0,"Tie",IF(H8<10,"Low sample",IF(AND(H8>=30,U8>=10),"Strong",IF(U8>=5,"Lean","Toss-up")))) -> Lean | W8: =IF(LARGE(I8:M8,1)=LARGE(I8:M8,2),"Tie",INDEX({"TVK","AIADMK+BJP+PMK+AMMK","DMK+INC+VCK","NTK","NOTA"},MATCH(MAX(I8:M8),I8:M8,0))) -> AIADMK+BJP+PMK+AMMK | X8: =MAX(N8:R8) -> 0.55285405 | Y8: =IF(ISNUMBER(MATCH(A8,{"Maduravoyal","Ambattur","Madavaram","Thiruvottiyur","Sholinganallur","Alandur"},0)),"Chennai",B8) -> Chengalpattu
A9: Madurantakam | B9: Chengalpattu | C9: 8 | D9: 5 | E9: 4 | F9: 1 | G9: 0 | H9: =SUM(C9:G9) -> 18 | I9: =IF($H9=0,0,C9/$H9) -> 0.44444444 | J9: =IF($H9=0,0,D9/$H9) -> 0.27777778 | K9: =IF($H9=0,0,E9/$H9) -> 0.22222222 | L9: =IF($H9=0,0,F9/$H9) -> 0.055555556 | M9: =IF($H9=0,0,G9/$H9) -> 0 | N9: =MAX(0,I9+'Statewide Votes'!$H$9/100) -> 0.39981785 | O9: =MAX(0,J9+'Statewide Votes'!$I$9/100) -> 0.28517728 | P9: =MAX(0,K9+'Statewide Votes'!$J$9/100) -> 0.26657018 | Q9: =MAX(0,L9+'Statewide Votes'!$K$9/100) -> 0.046772239 | R9: =MAX(0,M9+'Statewide Votes'!$L$9/100) -> 0.0016624482 | S9: =IF(U9=0,"Tie",INDEX({"TVK","AIADMK+BJP+PMK+AMMK","DMK+INC+VCK","NTK","NOTA"},MATCH(MAX(N9:R9),N9:R9,0))) -> TVK | T9: =INDEX({"TVK","AIADMK+BJP+PMK+AMMK","DMK+INC+VCK","NTK","NOTA"},MATCH(LARGE(N9:R9,2),N9:R9,0)) -> AIADMK+BJP+PMK+AMMK | U9: =ROUND((LARGE(N9:R9,1)-LARGE(N9:R9,2))*100,1) -> 11.5 | V9: =IF(U9=0,"Tie",IF(H9<10,"Low sample",IF(AND(H9>=30,U9>=10),"Strong",IF(U9>=5,"Lean","Toss-up")))) -> Lean | W9: =IF(LARGE(I9:M9,1)=LARGE(I9:M9,2),"Tie",INDEX({"TVK","AIADMK+BJP+PMK+AMMK","DMK+INC+VCK","NTK","NOTA"},MATCH(MAX(I9:M9),I9:M9,0))) -> TVK | X9: =MAX(N9:R9) -> 0.39981785 | Y9: =IF(ISNUMBER(MATCH(A9,{"Maduravoyal","Ambattur","Madavaram","Thiruvottiyur","Sholinganallur","Alandur"},0)),"Chennai",B9) -> Chengalpattu
A10: Pallavaram | B10: Chengalpattu | C10: 38 | D10: 26 | E10: 28 | F10: 4 | G10: 0 | H10: =SUM(C10:G10) -> 96 | I10: =IF($H10=0,0,C10/$H10) -> 0.39583333 | J10: =IF($H10=0,0,D10/$H10) -> 0.27083333 | K10: =IF($H10=0,0,E10/$H10) -> 0.29166667 | L10: =IF($H10=0,0,F10/$H10) -> 0.041666667 | M10: =IF($H10=0,0,G10/$H10) -> 0 | N10: =MAX(0,I10+'Statewide Votes'!$H$9/100) -> 0.35120674 | O10: =MAX(0,J10+'Statewide Votes'!$I$9/100) -> 0.27823284 | P10: =MAX(0,K10+'Statewide Votes'!$J$9/100) -> 0.33601462 | Q10: =MAX(0,L10+'Statewide Votes'!$K$9/100) -> 0.03288335 | R10: =MAX(0,M10+'Statewide Votes'!$L$9/100) -> 0.0016624482 | S10: =IF(U10=0,"Tie",INDEX({"TVK","AIADMK+BJP+PMK+AMMK","DMK+INC+VCK","NTK","NOTA"},MATCH(MAX(N10:R10),N10:R10,0))) -> TVK | T10: =INDEX({"TVK","AIADMK+BJP+PMK+AMMK","DMK+INC+VCK","NTK","NOTA"},MATCH(LARGE(N10:R10,2),N10:R10,0)) -> DMK+INC+VCK | U10: =ROUND((LARGE(N10:R10,1)-LARGE(N10:R10,2))*100,1) -> 1.5 | V10: =IF(U10=0,"Tie",IF(H10<10,"Low sample",IF(AND(H10>=30,U10>=10),"Strong",IF(U10>=5,"Lean","Toss-up")))) -> Toss-up | W10: =IF(LARGE(I10:M10,1)=LARGE(I10:M10,2),"Tie",INDEX({"TVK","AIADMK+BJP+PMK+AMMK","DMK+INC+VCK","NTK","NOTA"},MATCH(MAX(I10:M10),I10:M10,0))) -> TVK | X10: =MAX(N10:R10) -> 0.35120674 | Y10: =IF(ISNUMBER(MATCH(A10,{"Maduravoyal","Ambattur","Madavaram","Thiruvottiyur","Sholinganallur","Alandur"},0)),"Chennai",B10) -> Chengalpattu
A11: Sholinganallur | B11: Chengalpattu | C11: 45 | D11: 34 | E11: 22 | F11: 6 | G11: 1 | H11: =SUM(C11:G11) -> 108 | I11: =IF($H11=0,0,C11/$H11) -> 0.41666667 | J11: =IF($H11=0,0,D11/$H11) -> 0.31481481 | K11: =IF($H11=0,0,E11/$H11) -> 0.2037037 | L11: =IF($H11=0,0,F11/$H11) -> 0.055555556 | M11: =IF($H11=0,0,G11/$H11) -> 0.0092592593 | N11: =MAX(0,I11+'Statewide Votes'!$H$9/100) -> 0.37204007 | O11: =MAX(0,J11+'Statewide Votes'!$I$9/100) -> 0.32221432 | P11: =MAX(0,K11+'Statewide Votes'!$J$9/100) -> 0.24805166 | Q11: =MAX(0,L11+'Statewide Votes'!$K$9/100) -> 0.046772239 | R11: =MAX(0,M11+'Statewide Votes'!$L$9/100) -> 0.010921707 | S11: =IF(U11=0,"Tie",INDEX({"TVK","AIADMK+BJP+PMK+AMMK","DMK+INC+VCK","NTK","NOTA"},MATCH(MAX(N11:R11),N11:R11,0))) -> TVK | T11: =INDEX({"TVK","AIADMK+BJP+PMK+AMMK","DMK+INC+VCK","NTK","NOTA"},MATCH(LARGE(N11:R11,2),N11:R11,0)) -> AIADMK+BJP+PMK+AMMK | U11: =ROUND((LARGE(N11:R11,1)-LARGE(N11:R11,2))*100,1) -> 5 | V11: =IF(U11=0,"Tie",IF(H11<10,"Low sample",IF(AND(H11>=30,U11>=10),"Strong",IF(U11>=5,"Lean","Toss-up")))) -> Lean | W11: =IF(LARGE(I11:M11,1)=LARGE(I11:M11,2),"Tie",INDEX({"TVK","AIADMK+BJP+PMK+AMMK","DMK+INC+VCK","NTK","NOTA"},MATCH(MAX(I11:M11),I11:M11,0))) -> TVK | X11: =MAX(N11:R11) -> 0.37204007 | Y11: =IF(ISNUMBER(MATCH(A11,{"Maduravoyal","Ambattur","Madavaram","Thiruvottiyur","Sholinganallur","Alandur"},0)),"Chennai",B11) -> Chennai
A12: Tambaram | B12: Chengalpattu | C12: 31 | D12: 25 | E12: 24 | F12: 6 | G12: 2 | H12: =SUM(C12:G12) -> 88 | I12: =IF($H12=0,0,C12/$H12) -> 0.35227273 | J12: =IF($H12=0,0,D12/$H12) -> 0.28409091 | K12: =IF($H12=0,0,E12/$H12) -> 0.27272727 | L12: =IF($H12=0,0,F12/$H12) -> 0.068181818 | M12: =IF($H12=0,0,G12/$H12) -> 0.022727273 | N12: =MAX(0,I12+'Statewide Votes'!$H$9/100) -> 0.30764613 | O12: =MAX(0,J12+'Statewide Votes'!$I$9/100) -> 0.29149042 | P12: =MAX(0,K12+'Statewide Votes'!$J$9/100) -> 0.31707523 | Q12: =MAX(0,L12+'Statewide Votes'!$K$9/100) -> 0.059398501 | R12: =MAX(0,M12+'Statewide Votes'!$L$9/100) -> 0.024389721 | S12: =IF(U12=0,"Tie",INDEX({"TVK","AIADMK+BJP+PMK+AMMK","DMK+INC+VCK","NTK","NOTA"},MATCH(MAX(N12:R12),N12:R12,0))) -> DMK+INC+VCK | T12: =INDEX({"TVK","AIADMK+BJP+PMK+AMMK","DMK+INC+VCK","NTK","NOTA"},MATCH(LARGE(N12:R12,2),N12:R12,0)) -> TVK | U12: =ROUND((LARGE(N12:R12,1)-LARGE(N12:R12,2))*100,1) -> 0.9 | V12: =IF(U12=0,"Tie",IF(H12<10,"Low sample",IF(AND(H12>=30,U12>=10),"Strong",IF(U12>=5,"Lean","Toss-up")))) -> Toss-up | W12: =IF(LARGE(I12:M12,1)=LARGE(I12:M12,2),"Tie",INDEX({"TVK","AIADMK+BJP+PMK+AMMK","DMK+INC+VCK","NTK","NOTA"},MATCH(MAX(I12:M12),I12:M12,0))) -> TVK | X12: =MAX(N12:R12) -> 0.31707523 | Y12: =IF(ISNUMBER(MATCH(A12,{"Maduravoyal","Ambattur","Madavaram","Thiruvottiyur","Sholinganallur","Alandur"},0)),"Chennai",B12) -> Chengalpattu
A13: Thiruporur | B13: Chengalpattu | C13: 20 | D13: 7 | E13: 2 | F13: 5 | G13: 0 | H13: =SUM(C13:G13) -> 34 | I13: =IF($H13=0,0,C13/$H13) -> 0.58823529 | J13: =IF($H13=0,0,D13/$H13) -> 0.20588235 | K13: =IF($H13=0,0,E13/$H13) -> 0.058823529 | L13: =IF($H13=0,0,F13/$H13) -> 0.14705882 | M13: =IF($H13=0,0,G13/$H13) -> 0 | N13: =MAX(0,I13+'Statewide Votes'!$H$9/100) -> 0.5436087 | O13: =MAX(0,J13+'Statewide Votes'!$I$9/100) -> 0.21328186 | P13: =MAX(0,K13+'Statewide Votes'!$J$9/100) -> 0.10317149 | Q13: =MAX(0,L13+'Statewide Votes'!$K$9/100) -> 0.13827551 | R13: =MAX(0,M13+'Statewide Votes'!$L$9/100) -> 0.0016624482 | S13: =IF(U13=0,"Tie",INDEX({"TVK","AIADMK+BJP+PMK+AMMK","DMK+INC+VCK","NTK","NOTA"},MATCH(MAX(N13:R13),N13:R13,0))) -> TVK | T13: =INDEX({"TVK","AIADMK+BJP+PMK+AMMK","DMK+INC+VCK","NTK","NOTA"},MATCH(LARGE(N13:R13,2),N13:R13,0)) -> AIADMK+BJP+PMK+AMMK | U13: =ROUND((LARGE(N13:R13,1)-LARGE(N13:R13,2))*100,1) -> 33 | V13: =IF(U13=0,"Tie",IF(H13<10,"Low sample",IF(AND(H13>=30,U13>=10),"Strong",IF(U13>=5,"Lean","Toss-up")))) -> Strong | W13: =IF(LARGE(I13:M13,1)=LARGE(I13:M13,2),"Tie",INDEX({"TVK","AIADMK+BJP+PMK+AMMK","DMK+INC+VCK","NTK","NOTA"},MATCH(MAX(I13:M13),I13:M13,0))) -> TVK | X13: =MAX(N13:R13) -> 0.5436087 | Y13: =IF(ISNUMBER(MATCH(A13,{"Maduravoyal","Ambattur","Madavaram","Thiruvottiyur","Sholinganallur","Alandur"},0)),"Chennai",B13) -> Chengalpattu
A14: Anna Nagar | B14: Chennai | C14: 21 | D14: 14 | E14: 10 | F14: 2 | G14: 2 | H14: =SUM(C14:G14) -> 49 | I14: =IF($H14=0,0,C14/$H14) -> 0.42857143 | J14: =IF($H14=0,0,D14/$H14) -> 0.28571429 | K14: =IF($H14=0,0,E14/$H14) -> 0.20408163 | L14: =IF($H14=0,0,F14/$H14) -> 0.040816327 | M14: =IF($H14=0,0,G14/$H14) -> 0.040816327 | N14: =MAX(0,I14+'Statewide Votes'!$H$9/100) -> 0.38394483 | O14: =MAX(0,J14+'Statewide Votes'!$I$9/100) -> 0.29311379 | P14: =MAX(0,K14+'Statewide Votes'!$J$9/100) -> 0.24842959 | Q14: =MAX(0,L14+'Statewide Votes'!$K$9/100) -> 0.03203301 | R14: =MAX(0,M14+'Statewide Votes'!$L$9/100) -> 0.042478775 | S14: =IF(U14=0,"Tie",INDEX({"TVK","AIADMK+BJP+PMK+AMMK","DMK+INC+VCK","NTK","NOTA"},MATCH(MAX(N14:R14),N14:R14,0))) -> TVK | T14: =INDEX({"TVK","AIADMK+BJP+PMK+AMMK","DMK+INC+VCK","NTK","NOTA"},MATCH(LARGE(N14:R14,2),N14:R14,0)) -> AIADMK+BJP+PMK+AMMK | U14: =ROUND((LARGE(N14:R14,1)-LARGE(N14:R14,2))*100,1) -> 9.1 | V14: =IF(U14=0,"Tie",IF(H14<10,"Low sample",IF(AND(H14>=30,U14>=10),"Strong",IF(U14>=5,"Lean","Toss-up")))) -> Lean | W14: =IF(LARGE(I14:M14,1)=LARGE(I14:M14,2),"Tie",INDEX({"TVK","AIADMK+BJP+PMK+AMMK","DMK+INC+VCK","NTK","NOTA"},MATCH(MAX(I14:M14),I14:M14,0))) -> TVK | X14: =MAX(N14:R14) -> 0.38394483 | Y14: =IF(ISNUMBER(MATCH(A14,{"Maduravoyal","Ambattur","Madavaram","Thiruvottiyur","Sholinganallur","Alandur"},0)),"Chennai",B14) -> Chennai
A15: Chepauk-Thiruvallikeni | B15: Chennai | C15: 14 | D15: 9 | E15: 11 | F15: 1 | G15: 0 | H15: =SUM(C15:G15) -> 35 | I15: =IF($H15=0,0,C15/$H15) -> 0.4 | J15: =IF($H15=0,0,D15/$H15) -> 0.25714286 | K15: =IF($H15=0,0,E15/$H15) -> 0.31428571 | L15: =IF($H15=0,0,F15/$H15) -> 0.028571429 | M15: =IF($H15=0,0,G15/$H15) -> 0 | N15: =MAX(0,I15+'Statewide Votes'!$H$9/100) -> 0.35537341 | O15: =MAX(0,J15+'Statewide Votes'!$I$9/100) -> 0.26454236 | P15: =MAX(0,K15+'Statewide Votes'!$J$9/100) -> 0.35863367 | Q15: =MAX(0,L15+'Statewide Votes'!$K$9/100) -> 0.019788112 | R15: =MAX(0,M15+'Statewide Votes'!$L$9/100) -> 0.0016624482 | S15: =IF(U15=0,"Tie",INDEX({"TVK","AIADMK+BJP+PMK+AMMK","DMK+INC+VCK","NTK","NOTA"},MATCH(MAX(N15:R15),N15:R15,0))) -> DMK+INC+VCK | T15: =INDEX({"TVK","AIADMK+BJP+PMK+AMMK","DMK+INC+VCK","NTK","NOTA"},MATCH(LARGE(N15:R15,2),N15:R15,0)) -> TVK | U15: =ROUND((LARGE(N15:R15,1)-LARGE(N15:R15,2))*100,1) -> 0.3 | V15: =IF(U15=0,"Tie",IF(H15<10,"Low sample",IF(AND(H15>=30,U15>=10),"Strong",IF(U15>=5,"Lean","Toss-up")))) -> Toss-up | W15: =IF(LARGE(I15:M15,1)=LARGE(I15:M15,2),"Tie",INDEX({"TVK","AIADMK+BJP+PMK+AMMK","DMK+INC+VCK","NTK","NOTA"},MATCH(MAX(I15:M15),I15:M15,0))) -> TVK | X15: =MAX(N15:R15) -> 0.35863367 | Y15: =IF(ISNUMBER(MATCH(A15,{"Maduravoyal","Ambattur","Madavaram","Thiruvottiyur","Sholinganallur","Alandur"},0)),"Chennai",B15) -> Chennai
A16: Dr. Radhakrishnan Nagar | B16: Chennai | C16: 25 | D16: 10 | E16: 16 | F16: 3 | G16: 0 | H16: =SUM(C16:G16) -> 54 | I16: =IF($H16=0,0,C16/$H16) -> 0.46296296 | J16: =IF($H16=0,0,D16/$H16) -> 0.18518519 | K16: =IF($H16=0,0,E16/$H16) -> 0.2962963 | L16: =IF($H16=0,0,F16/$H16) -> 0.055555556 | M16: =IF($H16=0,0,G16/$H16) -> 0 | N16: =MAX(0,I16+'Statewide Votes'!$H$9/100) -> 0.41833637 | O16: =MAX(0,J16+'Statewide Votes'!$I$9/100) -> 0.19258469 | P16: =MAX(0,K16+'Statewide Votes'!$J$9/100) -> 0.34064425 | Q16: =MAX(0,L16+'Statewide Votes'!$K$9/100) -> 0.046772239 | R16: =MAX(0,M16+'Statewide Votes'!$L$9/100) -> 0.0016624482 | S16: =IF(U16=0,"Tie",INDEX({"TVK","AIADMK+BJP+PMK+AMMK","DMK+INC+VCK","NTK","NOTA"},MATCH(MAX(N16:R16),N16:R16,0))) -> TVK | T16: =INDEX({"TVK","AIADMK+BJP+PMK+AMMK","DMK+INC+VCK","NTK","NOTA"},MATCH(LARGE(N16:R16,2),N16:R16,0)) -> DMK+INC+VCK | U16: =ROUND((LARGE(N16:R16,1)-LARGE(N16:R16,2))*100,1) -> 7.8 | V16: =IF(U16=0,"Tie",IF(H16<10,"Low sample",IF(AND(H16>=30,U16>=10),"Strong",IF(U16>=5,"Lean","Toss-up")))) -> Lean | W16: =IF(LARGE(I16:M16,1)=LARGE(I16:M16,2),"Tie",INDEX({"TVK","AIADMK+BJP+PMK+AMMK","DMK+INC+VCK","NTK","NOTA"},MATCH(MAX(I16:M16),I16:M16,0))) -> TVK | X16: =MAX(N16:R16) -> 0.41833637 | Y16: =IF(ISNUMBER(MATCH(A16,{"Maduravoyal","Ambattur","Madavaram","Thiruvottiyur","Sholinganallur","Alandur"},0)),"Chennai",B16) -> Chennai
... A238: Virudhunagar | B238: Virudhunagar | C238: 19 | D238: 8 | E238: 14 | F238: 2 | G238: 0 | H238: =SUM(C238:G238) -> 43 | I238: =IF($H238=0,0,C238/$H238) -> 0.44186047 | J238: =IF($H238=0,0,D238/$H238) -> 0.18604651 | K238: =IF($H238=0,0,E238/$H238) -> 0.3255814 | L238: =IF($H238=0,0,F238/$H238) -> 0.046511628 | M238: =IF($H238=0,0,G238/$H238) -> 0 | N238: =MAX(0,I238+'Statewide Votes'!$H$9/100) -> 0.39723387 | O238: =MAX(0,J238+'Statewide Votes'!$I$9/100) -> 0.19344602 | P238: =MAX(0,K238+'Statewide Votes'!$J$9/100) -> 0.36992935 | Q238: =MAX(0,L238+'Statewide Votes'!$K$9/100) -> 0.037728311 | R238: =MAX(0,M238+'Statewide Votes'!$L$9/100) -> 0.0016624482 | S238: =IF(U238=0,"Tie",INDEX({"TVK","AIADMK+BJP+PMK+AMMK","DMK+INC+VCK","NTK","NOTA"},MATCH(MAX(N238:R238),N238:R238,0))) -> TVK | T238: =INDEX({"TVK","AIADMK+BJP+PMK+AMMK","DMK+INC+VCK","NTK","NOTA"},MATCH(LARGE(N238:R238,2),N238:R238,0)) -> DMK+INC+VCK | U238: =ROUND((LARGE(N238:R238,1)-LARGE(N238:R238,2))*100,1) -> 2.7 | V238: =IF(U238=0,"Tie",IF(H238<10,"Low sample",IF(AND(H238>=30,U238>=10),"Strong",IF(U238>=5,"Lean","Toss-up")))) -> Toss-up | W238: =IF(LARGE(I238:M238,1)=LARGE(I238:M238,2),"Tie",INDEX({"TVK","AIADMK+BJP+PMK+AMMK","DMK+INC+VCK","NTK","NOTA"},MATCH(MAX(I238:M238),I238:M238,0))) -> TVK | X238: =MAX(N238:R238) -> 0.39723387 | Y238: =IF(ISNUMBER(MATCH(A238,{"Maduravoyal","Ambattur","Madavaram","Thiruvottiyur","Sholinganallur","Alandur"},0)),"Chennai",B238) -> Virudhunagar
C239: =SUM(C4:C238) -> 4165 | D239: =SUM(D4:D238) -> 2898 | E239: =SUM(E4:E238) -> 2583 | F239: =SUM(F4:F238) -> 856 | G239: =SUM(G4:G238) -> 65 | I239: =AVERAGE(I4:I238) -> 0.38861606
C240: =C239/SUM(C239:G239) -> 0.3941516

Sheet District vs Actual 2026
A1: District seats — survey projection vs actual 2026 result
A2: Actual: ECI result declared 4 May 2026, constituency winners as listed by IndiaVotes (totals match ECI: TVK 108, DMK+ 73, AIADMK+ 53), summed by district. Districts follow the Wikipedia/ECI table: Chennai includes Maduravoyal, Ambattur, Madavaram, Thiruvottiyur, Sholinganallur and Alandur.
A4: District | B4: Seats | C4: Proj. TVK | D4: Proj. AIADMK+ | E4: Proj. DMK+ | F4: Proj. other / tie | G4: Actual TVK | H4: Actual AIADMK+ | I4: Actual DMK+ | J4: Actual − Proj. TVK | K4: Actual − Proj. AIADMK+ | L4: Actual − Proj. DMK+ | M4: Seat error (abs) | N4: Projected top party | O4: Actual top party | P4: Top party match? | Q4: TVK actual ≥ proj.? | R4: AIADMK+ actual ≥ proj.? | S4: DMK+ actual ≥ proj.?
A5: Thiruvallur | B5: =COUNTIF('AC Results'!$Y$5:$Y$238,$A5) -> 6 | C5: =COUNTIFS('AC Results'!$Y$5:$Y$238,$A5,'AC Results'!$S$5:$S$238,"TVK") -> 5 | D5: =COUNTIFS('AC Results'!$Y$5:$Y$238,$A5,'AC Results'!$S$5:$S$238,"AIADMK+BJP+PMK+AMMK") -> 0 | E5: =COUNTIFS('AC Results'!$Y$5:$Y$238,$A5,'AC Results'!$S$5:$S$238,"DMK+INC+VCK") -> 1 | F5: =B5-SUM(C5:E5) -> 0 | G5: =COUNTIFS('AC vs Actual 2026'!$C$5:$C$238,$A5,'AC vs Actual 2026'!$L$5:$L$238,"TVK") -> 5 | H5: =COUNTIFS('AC vs Actual 2026'!$C$5:$C$238,$A5,'AC vs Actual 2026'!$L$5:$L$238,"AIADMK+BJP+PMK+AMMK") -> 1 | I5: =COUNTIFS('AC vs Actual 2026'!$C$5:$C$238,$A5,'AC vs Actual 2026'!$L$5:$L$238,"DMK+INC+VCK") -> 0 | J5: =G5-C5 -> 0 | K5: =H5-D5 -> 1 | L5: =I5-E5 -> -1 | M5: =ABS(J5)+ABS(K5)+ABS(L5)+F5 -> 2 | N5: =IF(COUNTIF(C5:E5,MAX(C5:E5))>1,"Tie",INDEX({"TVK","AIADMK+","DMK+"},MATCH(MAX(C5:E5),C5:E5,0))) -> TVK | O5: =IF(COUNTIF(G5:I5,MAX(G5:I5))>1,"Tie",INDEX({"TVK","AIADMK+","DMK+"},MATCH(MAX(G5:I5),G5:I5,0))) -> TVK | P5: =IF(OR(N5="Tie",O5="Tie"),"Partly",IF(N5=O5,"Yes","No")) -> Yes | Q5: =IF(J5>=0,"Yes","No") -> Yes | R5: =IF(K5>=0,"Yes","No") -> Yes | S5: =IF(L5>=0,"Yes","No") -> No
A6: Chennai | B6: =COUNTIF('AC Results'!$Y$5:$Y$238,$A6) -> 22 | C6: =COUNTIFS('AC Results'!$Y$5:$Y$238,$A6,'AC Results'!$S$5:$S$238,"TVK") -> 13 | D6: =COUNTIFS('AC Results'!$Y$5:$Y$238,$A6,'AC Results'!$S$5:$S$238,"AIADMK+BJP+PMK+AMMK") -> 3 | E6: =COUNTIFS('AC Results'!$Y$5:$Y$238,$A6,'AC Results'!$S$5:$S$238,"DMK+INC+VCK") -> 6 | F6: =B6-SUM(C6:E6) -> 0 | G6: =COUNTIFS('AC vs Actual 2026'!$C$5:$C$238,$A6,'AC vs Actual 2026'!$L$5:$L$238,"TVK") -> 20 | H6: =COUNTIFS('AC vs Actual 2026'!$C$5:$C$238,$A6,'AC vs Actual 2026'!$L$5:$L$238,"AIADMK+BJP+PMK+AMMK") -> 0 | I6: =COUNTIFS('AC vs Actual 2026'!$C$5:$C$238,$A6,'AC vs Actual 2026'!$L$5:$L$238,"DMK+INC+VCK") -> 2 | J6: =G6-C6 -> 7 | K6: =H6-D6 -> -3 | L6: =I6-E6 -> -4 | M6: =ABS(J6)+ABS(K6)+ABS(L6)+F6 -> 14 | N6: =IF(COUNTIF(C6:E6,MAX(C6:E6))>1,"Tie",INDEX({"TVK","AIADMK+","DMK+"},MATCH(MAX(C6:E6),C6:E6,0))) -> TVK | O6: =IF(COUNTIF(G6:I6,MAX(G6:I6))>1,"Tie",INDEX({"TVK","AIADMK+","DMK+"},MATCH(MAX(G6:I6),G6:I6,0))) -> TVK | P6: =IF(OR(N6="Tie",O6="Tie"),"Partly",IF(N6=O6,"Yes","No")) -> Yes | Q6: =IF(J6>=0,"Yes","No") -> Yes | R6: =IF(K6>=0,"Yes","No") -> No | S6: =IF(L6>=0,"Yes","No") -> No
A7: Kancheepuram | B7: =COUNTIF('AC Results'!$Y$5:$Y$238,$A7) -> 3 | C7: =COUNTIFS('AC Results'!$Y$5:$Y$238,$A7,'AC Results'!$S$5:$S$238,"TVK") -> 1 | D7: =COUNTIFS('AC Results'!$Y$5:$Y$238,$A7,'AC Results'!$S$5:$S$238,"AIADMK+BJP+PMK+AMMK") -> 0 | E7: =COUNTIFS('AC Results'!$Y$5:$Y$238,$A7,'AC Results'!$S$5:$S$238,"DMK+INC+VCK") -> 2 | F7: =B7-SUM(C7:E7) -> 0 | G7: =COUNTIFS('AC vs Actual 2026'!$C$5:$C$238,$A7,'AC vs Actual 2026'!$L$5:$L$238,"TVK") -> 3 | H7: =COUNTIFS('AC vs Actual 2026'!$C$5:$C$238,$A7,'AC vs Actual 2026'!$L$5:$L$238,"AIADMK+BJP+PMK+AMMK") -> 0 | I7: =COUNTIFS('AC vs Actual 2026'!$C$5:$C$238,$A7,'AC vs Actual 2026'!$L$5:$L$238,"DMK+INC+VCK") -> 0 | J7: =G7-C7 -> 2 | K7: =H7-D7 -> 0 | L7: =I7-E7 -> -2 | M7: =ABS(J7)+ABS(K7)+ABS(L7)+F7 -> 4 | N7: =IF(COUNTIF(C7:E7,MAX(C7:E7))>1,"Tie",INDEX({"TVK","AIADMK+","DMK+"},MATCH(MAX(C7:E7),C7:E7,0))) -> DMK+ | O7: =IF(COUNTIF(G7:I7,MAX(G7:I7))>1,"Tie",INDEX({"TVK","AIADMK+","DMK+"},MATCH(MAX(G7:I7),G7:I7,0))) -> TVK | P7: =IF(OR(N7="Tie",O7="Tie"),"Partly",IF(N7=O7,"Yes","No")) -> No | Q7: =IF(J7>=0,"Yes","No") -> Yes | R7: =IF(K7>=0,"Yes","No") -> Yes | S7: =IF(L7>=0,"Yes","No") -> No
A8: Chengalpattu | B8: =COUNTIF('AC Results'!$Y$5:$Y$238,$A8) -> 6 | C8: =COUNTIFS('AC Results'!$Y$5:$Y$238,$A8,'AC Results'!$S$5:$S$238,"TVK") -> 4 | D8: =COUNTIFS('AC Results'!$Y$5:$Y$238,$A8,'AC Results'!$S$5:$S$238,"AIADMK+BJP+PMK+AMMK") -> 1 | E8: =COUNTIFS('AC Results'!$Y$5:$Y$238,$A8,'AC Results'!$S$5:$S$238,"DMK+INC+VCK") -> 1 | F8: =B8-SUM(C8:E8) -> 0 | G8: =COUNTIFS('AC vs Actual 2026'!$C$5:$C$238,$A8,'AC vs Actual 2026'!$L$5:$L$238,"TVK") -> 4 | H8: =COUNTIFS('AC vs Actual 2026'!$C$5:$C$238,$A8,'AC vs Actual 2026'!$L$5:$L$238,"AIADMK+BJP+PMK+AMMK") -> 2 | I8: =COUNTIFS('AC vs Actual 2026'!$C$5:$C$238,$A8,'AC vs Actual 2026'!$L$5:$L$238,"DMK+INC+VCK") -> 0 | J8: =G8-C8 -> 0 | K8: =H8-D8 -> 1 | L8: =I8-E8 -> -1 | M8: =ABS(J8)+ABS(K8)+ABS(L8)+F8 -> 2 | N8: =IF(COUNTIF(C8:E8,MAX(C8:E8))>1,"Tie",INDEX({"TVK","AIADMK+","DMK+"},MATCH(MAX(C8:E8),C8:E8,0))) -> TVK | O8: =IF(COUNTIF(G8:I8,MAX(G8:I8))>1,"Tie",INDEX({"TVK","AIADMK+","DMK+"},MATCH(MAX(G8:I8),G8:I8,0))) -> TVK | P8: =IF(OR(N8="Tie",O8="Tie"),"Partly",IF(N8=O8,"Yes","No")) -> Yes | Q8: =IF(J8>=0,"Yes","No") -> Yes | R8: =IF(K8>=0,"Yes","No") -> Yes | S8: =IF(L8>=0,"Yes","No") -> No
A9: Ranipet | B9: =COUNTIF('AC Results'!$Y$5:$Y$238,$A9) -> 4 | C9: =COUNTIFS('AC Results'!$Y$5:$Y$238,$A9,'AC Results'!$S$5:$S$238,"TVK") -> 1 | D9: =COUNTIFS('AC Results'!$Y$5:$Y$238,$A9,'AC Results'!$S$5:$S$238,"AIADMK+BJP+PMK+AMMK") -> 2 | E9: =COUNTIFS('AC Results'!$Y$5:$Y$238,$A9,'AC Results'!$S$5:$S$238,"DMK+INC+VCK") -> 1 | F9: =B9-SUM(C9:E9) -> 0 | G9: =COUNTIFS('AC vs Actual 2026'!$C$5:$C$238,$A9,'AC vs Actual 2026'!$L$5:$L$238,"TVK") -> 3 | H9: =COUNTIFS('AC vs Actual 2026'!$C$5:$C$238,$A9,'AC vs Actual 2026'!$L$5:$L$238,"AIADMK+BJP+PMK+AMMK") -> 1 | I9: =COUNTIFS('AC vs Actual 2026'!$C$5:$C$238,$A9,'AC vs Actual 2026'!$L$5:$L$238,"DMK+INC+VCK") -> 0 | J9: =G9-C9 -> 2 | K9: =H9-D9 -> -1 | L9: =I9-E9 -> -1 | M9: =ABS(J9)+ABS(K9)+ABS(L9)+F9 -> 4 | N9: =IF(COUNTIF(C9:E9,MAX(C9:E9))>1,"Tie",INDEX({"TVK","AIADMK+","DMK+"},MATCH(MAX(C9:E9),C9:E9,0))) -> AIADMK+ | O9: =IF(COUNTIF(G9:I9,MAX(G9:I9))>1,"Tie",INDEX({"TVK","AIADMK+","DMK+"},MATCH(MAX(G9:I9),G9:I9,0))) -> TVK | P9: =IF(OR(N9="Tie",O9="Tie"),"Partly",IF(N9=O9,"Yes","No")) -> No | Q9: =IF(J9>=0,"Yes","No") -> Yes | R9: =IF(K9>=0,"Yes","No") -> No | S9: =IF(L9>=0,"Yes","No") -> No
A10: Vellore | B10: =COUNTIF('AC Results'!$Y$5:$Y$238,$A10) -> 5 | C10: =COUNTIFS('AC Results'!$Y$5:$Y$238,$A10,'AC Results'!$S$5:$S$238,"TVK") -> 3 | D10: =COUNTIFS('AC Results'!$Y$5:$Y$238,$A10,'AC Results'!$S$5:$S$238,"AIADMK+BJP+PMK+AMMK") -> 1 | E10: =COUNTIFS('AC Results'!$Y$5:$Y$238,$A10,'AC Results'!$S$5:$S$238,"DMK+INC+VCK") -> 1 | F10: =B10-SUM(C10:E10) -> 0 | G10: =COUNTIFS('AC vs Actual 2026'!$C$5:$C$238,$A10,'AC vs Actual 2026'!$L$5:$L$238,"TVK") -> 4 | H10: =COUNTIFS('AC vs Actual 2026'!$C$5:$C$238,$A10,'AC vs Actual 2026'!$L$5:$L$238,"AIADMK+BJP+PMK+AMMK") -> 1 | I10: =COUNTIFS('AC vs Actual 2026'!$C$5:$C$238,$A10,'AC vs Actual 2026'!$L$5:$L$238,"DMK+INC+VCK") -> 0 | J10: =G10-C10 -> 1 | K10: =H10-D10 -> 0 | L10: =I10-E10 -> -1 | M10: =ABS(J10)+ABS(K10)+ABS(L10)+F10 -> 2 | N10: =IF(COUNTIF(C10:E10,MAX(C10:E10))>1,"Tie",INDEX({"TVK","AIADMK+","DMK+"},MATCH(MAX(C10:E10),C10:E10,0))) -> TVK | O10: =IF(COUNTIF(G10:I10,MAX(G10:I10))>1,"Tie",INDEX({"TVK","AIADMK+","DMK+"},MATCH(MAX(G10:I10),G10:I10,0))) -> TVK | P10: =IF(OR(N10="Tie",O10="Tie"),"Partly",IF(N10=O10,"Yes","No")) -> Yes | Q10: =IF(J10>=0,"Yes","No") -> Yes | R10: =IF(K10>=0,"Yes","No") -> Yes | S10: =IF(L10>=0,"Yes","No") -> No
A11: Tirupathur | B11: =COUNTIF('AC Results'!$Y$5:$Y$238,$A11) -> 4 | C11: =COUNTIFS('AC Results'!$Y$5:$Y$238,$A11,'AC Results'!$S$5:$S$238,"TVK") -> 2 | D11: =COUNTIFS('AC Results'!$Y$5:$Y$238,$A11,'AC Results'!$S$5:$S$238,"AIADMK+BJP+PMK+AMMK") -> 0 | E11: =COUNTIFS('AC Results'!$Y$5:$Y$238,$A11,'AC Results'!$S$5:$S$238,"DMK+INC+VCK") -> 2 | F11: =B11-SUM(C11:E11) -> 0 | G11: =COUNTIFS('AC vs Actual 2026'!$C$5:$C$238,$A11,'AC vs Actual 2026'!$L$5:$L$238,"TVK") -> 1 | H11: =COUNTIFS('AC vs Actual 2026'!$C$5:$C$238,$A11,'AC vs Actual 2026'!$L$5:$L$238,"AIADMK+BJP+PMK+AMMK") -> 1 | I11: =COUNTIFS('AC vs Actual 2026'!$C$5:$C$238,$A11,'AC vs Actual 2026'!$L$5:$L$238,"DMK+INC+VCK") -> 2 | J11: =G11-C11 -> -1 | K11: =H11-D11 -> 1 | L11: =I11-E11 -> 0 | M11: =ABS(J11)+ABS(K11)+ABS(L11)+F11 -> 2 | N11: =IF(COUNTIF(C11:E11,MAX(C11:E11))>1,"Tie",INDEX({"TVK","AIADMK+","DMK+"},MATCH(MAX(C11:E11),C11:E11,0))) -> Tie | O11: =IF(COUNTIF(G11:I11,MAX(G11:I11))>1,"Tie",INDEX({"TVK","AIADMK+","DMK+"},MATCH(MAX(G11:I11),G11:I11,0))) -> DMK+ | P11: =IF(OR(N11="Tie",O11="Tie"),"Partly",IF(N11=O11,"Yes","No")) -> Partly | Q11: =IF(J11>=0,"Yes","No") -> No | R11: =IF(K11>=0,"Yes","No") -> Yes | S11: =IF(L11>=0,"Yes","No") -> Yes
A12: Krishnagiri | B12: =COUNTIF('AC Results'!$Y$5:$Y$238,$A12) -> 6 | C12: =COUNTIFS('AC Results'!$Y$5:$Y$238,$A12,'AC Results'!$S$5:$S$238,"TVK") -> 4 | D12: =COUNTIFS('AC Results'!$Y$5:$Y$238,$A12,'AC Results'!$S$5:$S$238,"AIADMK+BJP+PMK+AMMK") -> 2 | E12: =COUNTIFS('AC Results'!$Y$5:$Y$238,$A12,'AC Results'!$S$5:$S$238,"DMK+INC+VCK") -> 0 | F12: =B12-SUM(C12:E12) -> 0 | G12: =COUNTIFS('AC vs Actual 2026'!$C$5:$C$238,$A12,'AC vs Actual 2026'!$L$5:$L$238,"TVK") -> 2 | H12: =COUNTIFS('AC vs Actual 2026'!$C$5:$C$238,$A12,'AC vs Actual 2026'!$L$5:$L$238,"AIADMK+BJP+PMK+AMMK") -> 2 | I12: =COUNTIFS('AC vs Actual 2026'!$C$5:$C$238,$A12,'AC vs Actual 2026'!$L$5:$L$238,"DMK+INC+VCK") -> 2 | J12: =G12-C12 -> -2 | K12: =H12-D12 -> 0 | L12: =I12-E12 -> 2 | M12: =ABS(J12)+ABS(K12)+ABS(L12)+F12 -> 4 | N12: =IF(COUNTIF(C12:E12,MAX(C12:E12))>1,"Tie",INDEX({"TVK","AIADMK+","DMK+"},MATCH(MAX(C12:E12),C12:E12,0))) -> TVK | O12: =IF(COUNTIF(G12:I12,MAX(G12:I12))>1,"Tie",INDEX({"TVK","AIADMK+","DMK+"},MATCH(MAX(G12:I12),G12:I12,0))) -> Tie | P12: =IF(OR(N12="Tie",O12="Tie"),"Partly",IF(N12=O12,"Yes","No")) -> Partly | Q12: =IF(J12>=0,"Yes","No") -> No | R12: =IF(K12>=0,"Yes","No") -> Yes | S12: =IF(L12>=0,"Yes","No") -> Yes
A13: Dharmapuri | B13: =COUNTIF('AC Results'!$Y$5:$Y$238,$A13) -> 5 | C13: =COUNTIFS('AC Results'!$Y$5:$Y$238,$A13,'AC Results'!$S$5:$S$238,"TVK") -> 1 | D13: =COUNTIFS('AC Results'!$Y$5:$Y$238,$A13,'AC Results'!$S$5:$S$238,"AIADMK+BJP+PMK+AMMK") -> 4 | E13: =COUNTIFS('AC Results'!$Y$5:$Y$238,$A13,'AC Results'!$S$5:$S$238,"DMK+INC+VCK") -> 0 | F13: =B13-SUM(C13:E13) -> 0 | G13: =COUNTIFS('AC vs Actual 2026'!$C$5:$C$238,$A13,'AC vs Actual 2026'!$L$5:$L$238,"TVK") -> 1 | H13: =COUNTIFS('AC vs Actual 2026'!$C$5:$C$238,$A13,'AC vs Actual 2026'!$L$5:$L$238,"AIADMK+BJP+PMK+AMMK") -> 4 | I13: =COUNTIFS('AC vs Actual 2026'!$C$5:$C$238,$A13,'AC vs Actual 2026'!$L$5:$L$238,"DMK+INC+VCK") -> 0 | J13: =G13-C13 -> 0 | K13: =H13-D13 -> 0 | L13: =I13-E13 -> 0 | M13: =ABS(J13)+ABS(K13)+ABS(L13)+F13 -> 0 | N13: =IF(COUNTIF(C13:E13,MAX(C13:E13))>1,"Tie",INDEX({"TVK","AIADMK+","DMK+"},MATCH(MAX(C13:E13),C13:E13,0))) -> AIADMK+ | O13: =IF(COUNTIF(G13:I13,MAX(G13:I13))>1,"Tie",INDEX({"TVK","AIADMK+","DMK+"},MATCH(MAX(G13:I13),G13:I13,0))) -> AIADMK+ | P13: =IF(OR(N13="Tie",O13="Tie"),"Partly",IF(N13=O13,"Yes","No")) -> Yes | Q13: =IF(J13>=0,"Yes","No") -> Yes | R13: =IF(K13>=0,"Yes","No") -> Yes | S13: =IF(L13>=0,"Yes","No") -> Yes
A14: Tiruvannamalai | B14: =COUNTIF('AC Results'!$Y$5:$Y$238,$A14) -> 8 | C14: =COUNTIFS('AC Results'!$Y$5:$Y$238,$A14,'AC Results'!$S$5:$S$238,"TVK") -> 6 | D14: =COUNTIFS('AC Results'!$Y$5:$Y$238,$A14,'AC Results'!$S$5:$S$238,"AIADMK+BJP+PMK+AMMK") -> 1 | E14: =COUNTIFS('AC Results'!$Y$5:$Y$238,$A14,'AC Results'!$S$5:$S$238,"DMK+INC+VCK") -> 1 | F14: =B14-SUM(C14:E14) -> 0 | G14: =COUNTIFS('AC vs Actual 2026'!$C$5:$C$238,$A14,'AC vs Actual 2026'!$L$5:$L$238,"TVK") -> 1 | H14: =COUNTIFS('AC vs Actual 2026'!$C$5:$C$238,$A14,'AC vs Actual 2026'!$L$5:$L$238,"AIADMK+BJP+PMK+AMMK") -> 5 | I14: =COUNTIFS('AC vs Actual 2026'!$C$5:$C$238,$A14,'AC vs Actual 2026'!$L$5:$L$238,"DMK+INC+VCK") -> 2 | J14: =G14-C14 -> -5 | K14: =H14-D14 -> 4 | L14: =I14-E14 -> 1 | M14: =ABS(J14)+ABS(K14)+ABS(L14)+F14 -> 10 | N14: =IF(COUNTIF(C14:E14,MAX(C14:E14))>1,"Tie",INDEX({"TVK","AIADMK+","DMK+"},MATCH(MAX(C14:E14),C14:E14,0))) -> TVK | O14: =IF(COUNTIF(G14:I14,MAX(G14:I14))>1,"Tie",INDEX({"TVK","AIADMK+","DMK+"},MATCH(MAX(G14:I14),G14:I14,0))) -> AIADMK+ | P14: =IF(OR(N14="Tie",O14="Tie"),"Partly",IF(N14=O14,"Yes","No")) -> No | Q14: =IF(J14>=0,"Yes","No") -> No | R14: =IF(K14>=0,"Yes","No") -> Yes | S14: =IF(L14>=0,"Yes","No") -> Yes
A15: Villupuram | B15: =COUNTIF('AC Results'!$Y$5:$Y$238,$A15) -> 7 | C15: =COUNTIFS('AC Results'!$Y$5:$Y$238,$A15,'AC Results'!$S$5:$S$238,"TVK") -> 0 | D15: =COUNTIFS('AC Results'!$Y$5:$Y$238,$A15,'AC Results'!$S$5:$S$238,"AIADMK+BJP+PMK+AMMK") -> 6 | E15: =COUNTIFS('AC Results'!$Y$5:$Y$238,$A15,'AC Results'!$S$5:$S$238,"DMK+INC+VCK") -> 1 | F15: =B15-SUM(C15:E15) -> 0 | G15: =COUNTIFS('AC vs Actual 2026'!$C$5:$C$238,$A15,'AC vs Actual 2026'!$L$5:$L$238,"TVK") -> 0 | H15: =COUNTIFS('AC vs Actual 2026'!$C$5:$C$238,$A15,'AC vs Actual 2026'!$L$5:$L$238,"AIADMK+BJP+PMK+AMMK") -> 4 | I15: =COUNTIFS('AC vs Actual 2026'!$C$5:$C$238,$A15,'AC vs Actual 2026'!$L$5:$L$238,"DMK+INC+VCK") -> 3 | J15: =G15-C15 -> 0 | K15: =H15-D15 -> -2 | L15: =I15-E15 -> 2 | M15: =ABS(J15)+ABS(K15)+ABS(L15)+F15 -> 4 | N15: =IF(COUNTIF(C15:E15,MAX(C15:E15))>1,"Tie",INDEX({"TVK","AIADMK+","DMK+"},MATCH(MAX(C15:E15),C15:E15,0))) -> AIADMK+ | O15: =IF(COUNTIF(G15:I15,MAX(G15:I15))>1,"Tie",INDEX({"TVK","AIADMK+","DMK+"},MATCH(MAX(G15:I15),G15:I15,0))) -> AIADMK+ | P15: =IF(OR(N15="Tie",O15="Tie"),"Partly",IF(N15=O15,"Yes","No")) -> Yes | Q15: =IF(J15>=0,"Yes","No") -> Yes | R15: =IF(K15>=0,"Yes","No") -> No | S15: =IF(L15>=0,"Yes","No") -> Yes
A16: Kallakurichi | B16: =COUNTIF('AC Results'!$Y$5:$Y$238,$A16) -> 4 | C16: =COUNTIFS('AC Results'!$Y$5:$Y$238,$A16,'AC Results'!$S$5:$S$238,"TVK") -> 4 | D16: =COUNTIFS('AC Results'!$Y$5:$Y$238,$A16,'AC Results'!$S$5:$S$238,"AIADMK+BJP+PMK+AMMK") -> 0 | E16: =COUNTIFS('AC Results'!$Y$5:$Y$238,$A16,'AC Results'!$S$5:$S$238,"DMK+INC+VCK") -> 0 | F16: =B16-SUM(C16:E16) -> 0 | G16: =COUNTIFS('AC vs Actual 2026'!$C$5:$C$238,$A16,'AC vs Actual 2026'!$L$5:$L$238,"TVK") -> 1 | H16: =COUNTIFS('AC vs Actual 2026'!$C$5:$C$238,$A16,'AC vs Actual 2026'!$L$5:$L$238,"AIADMK+BJP+PMK+AMMK") -> 1 | I16: =COUNTIFS('AC vs Actual 2026'!$C$5:$C$238,$A16,'AC vs Actual 2026'!$L$5:$L$238,"DMK+INC+VCK") -> 2 | J16: =G16-C16 -> -3 | K16: =H16-D16 -> 1 | L16: =I16-E16 -> 2 | M16: =ABS(J16)+ABS(K16)+ABS(L16)+F16 -> 6 | N16: =IF(COUNTIF(C16:E16,MAX(C16:E16))>1,"Tie",INDEX({"TVK","AIADMK+","DMK+"},MATCH(MAX(C16:E16),C16:E16,0))) -> TVK | O16: =IF(COUNTIF(G16:I16,MAX(G16:I16))>1,"Tie",INDEX({"TVK","AIADMK+","DMK+"},MATCH(MAX(G16:I16),G16:I16,0))) -> DMK+ | P16: =IF(OR(N16="Tie",O16="Tie"),"Partly",IF(N16=O16,"Yes","No")) -> No | Q16: =IF(J16>=0,"Yes","No") -> No | R16: =IF(K16>=0,"Yes","No") -> Yes | S16: =IF(L16>=0,"Yes","No") -> Yes
... A42: Kanniyakumari | B42: =COUNTIF('AC Results'!$Y$5:$Y$238,$A42) -> 6 | C42: =COUNTIFS('AC Results'!$Y$5:$Y$238,$A42,'AC Results'!$S$5:$S$238,"TVK") -> 3 | D42: =COUNTIFS('AC Results'!$Y$5:$Y$238,$A42,'AC Results'!$S$5:$S$238,"AIADMK+BJP+PMK+AMMK") -> 2 | E42: =COUNTIFS('AC Results'!$Y$5:$Y$238,$A42,'AC Results'!$S$5:$S$238,"DMK+INC+VCK") -> 1 | F42: =B42-SUM(C42:E42) -> 0 | G42: =COUNTIFS('AC vs Actual 2026'!$C$5:$C$238,$A42,'AC vs Actual 2026'!$L$5:$L$238,"TVK") -> 0 | H42: =COUNTIFS('AC vs Actual 2026'!$C$5:$C$238,$A42,'AC vs Actual 2026'!$L$5:$L$238,"AIADMK+BJP+PMK+AMMK") -> 1 | I42: =COUNTIFS('AC vs Actual 2026'!$C$5:$C$238,$A42,'AC vs Actual 2026'!$L$5:$L$238,"DMK+INC+VCK") -> 5 | J42: =G42-C42 -> -3 | K42: =H42-D42 -> -1 | L42: =I42-E42 -> 4 | M42: =ABS(J42)+ABS(K42)+ABS(L42)+F42 -> 8 | N42: =IF(COUNTIF(C42:E42,MAX(C42:E42))>1,"Tie",INDEX({"TVK","AIADMK+","DMK+"},MATCH(MAX(C42:E42),C42:E42,0))) -> TVK | O42: =IF(COUNTIF(G42:I42,MAX(G42:I42))>1,"Tie",INDEX({"TVK","AIADMK+","DMK+"},MATCH(MAX(G42:I42),G42:I42,0))) -> DMK+ | P42: =IF(OR(N42="Tie",O42="Tie"),"Partly",IF(N42=O42,"Yes","No")) -> No | Q42: =IF(J42>=0,"Yes","No") -> No | R42: =IF(K42>=0,"Yes","No") -> No | S42: =IF(L42>=0,"Yes","No") -> Yes
A43: Tamil Nadu | B43: =SUM(B5:B42) -> 234 | C43: =SUM(C5:C42) -> 115 | D43: =SUM(D5:D42) -> 60 | E43: =SUM(E5:E42) -> 56 | F43: =SUM(F5:F42) -> 3 | G43: =SUM(G5:G42) -> 108 | H43: =SUM(H5:H42) -> 53 | I43: =SUM(I5:I42) -> 73 | ... M43: =SUM(M5:M42) -> 170 | Q43: =COUNTIF(Q5:Q42,"Yes")&" of 38 Yes" -> 21 of 38 Yes | R43: =COUNTIF(R5:R42,"Yes")&" of 38 Yes" -> 22 of 38 Yes | S43: =COUNTIF(S5:S42,"Yes")&" of 38 Yes" -> 26 of 38 Yes
A45: Accuracy
A46: Districts where projected top party = actual top party | B46: =COUNTIF(P5:P42,"Yes") -> 13
A47: Districts with a tie on either side | B47: =COUNTIF(P5:P42,"Partly") -> 9
A48: Districts missed | B48: =COUNTIF(P5:P42,"No") -> 16
A49: Hit rate (excluding ties) | B49: =IFERROR(B46/(B46+B48),0) -> 0.44827586
A50: Seats called for the right party (min of projected and actual, summed) | B50: =SUMPRODUCT((C5:C42<G5:G42)*C5:C42+(C5:C42>=G5:G42)*G5:G42)+SUMPRODUCT((D5:D42<H5:H42)*D5:D42+(D5:D42>=H5:H42)*H5:H42)+SUMPRODUCT((E5:E42<I5:I42)*E5:E42+(E5:E42>=I5:I42)*I5:I42) -> 149
A51: Share of 234 seats matched at district level | B51: =B50/234 -> 0.63675214
A52: Total absolute seat error | B52: =M43 -> 170
A53: Districts where TVK actual ≥ projected | B53: =COUNTIF(Q5:Q42,"Yes") -> 21
A54: Districts where AIADMK+ actual ≥ projected | B54: =COUNTIF(R5:R42,"Yes") -> 22
A55: Districts where DMK+ actual ≥ projected | B55: =COUNTIF(S5:S42,"Yes") -> 26
A58: Statewide — survey vs actual 2026
A59: Measure | B59: TVK | C59: AIADMK+ | D59: DMK+ | E59: NTK | F59: NOTA / others
A60: Survey vote share (all 31,316) | B60: ='Statewide Votes'!H5 -> 0.34780943 | C60: ='Statewide Votes'!I5 -> 0.28279474 | D60: ='Statewide Votes'!J5 -> 0.29205518 | E60: ='Statewide Votes'!K5 -> 0.069389449 | F60: ='Statewide Votes'!L5 -> 0.0079512071
A61: Actual vote share (ECI) | B61: 0.3502 | C61: 0.2721 | D61: 0.314 | E61: 0.04 | F61: 0.0237
A62: Actual − survey (pts) | B62: =(B61-B60)*100 -> 0.23905735 | C62: =(C61-C60)*100 -> -1.0694738 | D62: =(D61-D60)*100 -> 2.1944821 | E62: =(E61-E60)*100 -> -2.9389449 | F62: =(F61-F60)*100 -> 1.5748793
A63: Projected seats (survey) | B63: =C43 -> 115 | C63: =D43 -> 60 | D63: =E43 -> 56 | E63: =COUNTIF('AC Results'!$S$5:$S$238,"NTK") -> 3 | F63: =F43-COUNTIF('AC Results'!$S$5:$S$238,"NTK") -> 0
A64: Actual seats (ECI) | B64: 108 | C64: 53 | D64: 73 | E64: 0 | F64: 0
A65: Actual − projected seats | B65: =B64-B63 -> -7 | C65: =C64-C63 -> -7 | D65: =D64-D63 -> 17 | E65: =E64-E63 -> -3 | F65: =F64-F63 -> 0
A66: Actual ≥ projected? | B66: =IF(B65>=0,"Yes","No") -> No | C66: =IF(C65>=0,"Yes","No") -> No | D66: =IF(D65>=0,"Yes","No") -> Yes | E66: =IF(E65>=0,"Yes","No") -> No | F66: =IF(F65>=0,"Yes","No") -> Yes
A67: Actual alliance totals: DMK+ includes DMDK (1 seat); AIADMK+ includes AMMK (1 seat). District seats are now summed from the constituency winners, so they match the ECI party totals (Wikipedia's district table sums to 72 / 54).

Sheet AC vs Actual 2026
A1: Constituency-wise — survey prediction vs actual 2026 winner
A2: Actual 2026 winners: ECI result (4 May 2026) as listed by IndiaVotes (indiavotes.com/compare/vidhan-sabha/tamil-nadu/2021/2026); party totals match the ECI tally (TVK 108, DMK 59, AIADMK 47, INC 5, PMK 4 …). 2021: ECI. Prediction: AC Results sheet (shifted to all 31,316 votes).
A4: AC No | B4: Constituency | C4: District (2026 ECI grouping) | D4: 2021 winner party | E4: 2021 alliance | F4: Survey n | G4: Predicted winner | H4: Predicted margin (pts) | I4: Confidence | J4: Prediction before shift | K4: Actual 2026 winner party | L4: Actual 2026 alliance | M4: Match? | N4: Match before shift? | O4: Alliance changed 2021→2026? | Q4: Accuracy summary
A5: 1 | B5: ='AC Results'!A168 -> Gummidipoondi | C5: ='AC Results'!Y168 -> Thiruvallur | D5: DMK | E5: DMK+INC+VCK | F5: ='AC Results'!H168 -> 45 | G5: ='AC Results'!S168 -> TVK | H5: ='AC Results'!U168 -> 13.3 | I5: ='AC Results'!V168 -> Strong | J5: ='AC Results'!W168 -> TVK | K5: TVK | L5: TVK | M5: =IF(G5=L5,"Yes","No") -> Yes | N5: =IF(J5=L5,"Yes","No") -> Yes | O5: =IF(E5<>L5,"Changed","Held") -> Changed | R5: Seats predicted correctly | S5: =COUNTIF($M$5:$M$238,"Yes") -> 110
A6: 2 | B6: ='AC Results'!A171 -> Ponneri | C6: ='AC Results'!Y171 -> Thiruvallur | D6: INC | E6: DMK+INC+VCK | F6: ='AC Results'!H171 -> 78 | G6: ='AC Results'!S171 -> TVK | H6: ='AC Results'!U171 -> 20.6 | I6: ='AC Results'!V171 -> Strong | J6: ='AC Results'!W171 -> TVK | K6: TVK | L6: TVK | M6: =IF(G6=L6,"Yes","No") -> Yes | N6: =IF(J6=L6,"Yes","No") -> Yes | O6: =IF(E6<>L6,"Changed","Held") -> Changed | R6: Accuracy | S6: =S5/234 -> 0.47008547
A7: 3 | B7: ='AC Results'!A175 -> Tiruttani | C7: ='AC Results'!Y175 -> Thiruvallur | D7: DMK | E7: DMK+INC+VCK | F7: ='AC Results'!H175 -> 59 | G7: ='AC Results'!S175 -> TVK | H7: ='AC Results'!U175 -> 8.1 | I7: ='AC Results'!V175 -> Lean | J7: ='AC Results'!W175 -> TVK | K7: ADMK | L7: AIADMK+BJP+PMK+AMMK | M7: =IF(G7=L7,"Yes","No") -> No | N7: =IF(J7=L7,"Yes","No") -> No | O7: =IF(E7<>L7,"Changed","Held") -> Changed | R7: Correct before shift | S7: =COUNTIF($N$5:$N$238,"Yes") -> 105
A8: 4 | B8: ='AC Results'!A173 -> Thiruvallur | C8: ='AC Results'!Y173 -> Thiruvallur | D8: DMK | E8: DMK+INC+VCK | F8: ='AC Results'!H173 -> 110 | G8: ='AC Results'!S173 -> TVK | H8: ='AC Results'!U173 -> 12.9 | I8: ='AC Results'!V173 -> Strong | J8: ='AC Results'!W173 -> TVK | K8: TVK | L8: TVK | M8: =IF(G8=L8,"Yes","No") -> Yes | N8: =IF(J8=L8,"Yes","No") -> Yes | O8: =IF(E8<>L8,"Changed","Held") -> Changed | R8: Accuracy before shift | S8: =S7/234 -> 0.44871795
A9: 5 | B9: ='AC Results'!A172 -> Poonamallee | C9: ='AC Results'!Y172 -> Thiruvallur | D9: DMK | E9: DMK+INC+VCK | F9: ='AC Results'!H172 -> 82 | G9: ='AC Results'!S172 -> TVK | H9: ='AC Results'!U172 -> 9.4 | I9: ='AC Results'!V172 -> Lean | J9: ='AC Results'!W172 -> TVK | K9: TVK | L9: TVK | M9: =IF(G9=L9,"Yes","No") -> Yes | N9: =IF(J9=L9,"Yes","No") -> Yes | O9: =IF(E9<>L9,"Changed","Held") -> Changed | R9: Baseline: every seat to TVK | S9: =COUNTIF($L$5:$L$238,"TVK")/234 -> 0.46153846
A10: 6 | B10: ='AC Results'!A167 -> Avadi | C10: ='AC Results'!Y167 -> Thiruvallur | D10: DMK | E10: DMK+INC+VCK | F10: ='AC Results'!H167 -> 117 | G10: ='AC Results'!S167 -> DMK+INC+VCK | H10: ='AC Results'!U167 -> 2.9 | I10: ='AC Results'!V167 -> Toss-up | J10: ='AC Results'!W167 -> TVK | K10: TVK | L10: TVK | M10: =IF(G10=L10,"Yes","No") -> No | N10: =IF(J10=L10,"Yes","No") -> Yes | O10: =IF(E10<>L10,"Changed","Held") -> Changed | R10: Baseline: 2021 alliance holds | S10: =COUNTIF($O$5:$O$238,"Held")/234 -> 0.33333333
A11: 7 | B11: ='AC Results'!A170 -> Maduravoyal | C11: ='AC Results'!Y170 -> Chennai | D11: DMK | E11: DMK+INC+VCK | F11: ='AC Results'!H170 -> 105 | G11: ='AC Results'!S170 -> TVK | H11: ='AC Results'!U170 -> 14.8 | I11: ='AC Results'!V170 -> Strong | J11: ='AC Results'!W170 -> TVK | K11: TVK | L11: TVK | M11: =IF(G11=L11,"Yes","No") -> Yes | N11: =IF(J11=L11,"Yes","No") -> Yes | O11: =IF(E11<>L11,"Changed","Held") -> Changed
A12: 8 | B12: ='AC Results'!A166 -> Ambattur | C12: ='AC Results'!Y166 -> Chennai | D12: DMK | E12: DMK+INC+VCK | F12: ='AC Results'!H166 -> 87 | G12: ='AC Results'!S166 -> TVK | H12: ='AC Results'!U166 -> 2.6 | I12: ='AC Results'!V166 -> Toss-up | J12: ='AC Results'!W166 -> TVK | K12: TVK | L12: TVK | M12: =IF(G12=L12,"Yes","No") -> Yes | N12: =IF(J12=L12,"Yes","No") -> Yes | O12: =IF(E12<>L12,"Changed","Held") -> Changed | R12: Accuracy by confidence
A13: 9 | B13: ='AC Results'!A169 -> Madavaram | C13: ='AC Results'!Y169 -> Chennai | D13: DMK | E13: DMK+INC+VCK | F13: ='AC Results'!H169 -> 78 | G13: ='AC Results'!S169 -> TVK | H13: ='AC Results'!U169 -> 10.2 | I13: ='AC Results'!V169 -> Strong | J13: ='AC Results'!W169 -> TVK | K13: TVK | L13: TVK | M13: =IF(G13=L13,"Yes","No") -> Yes | N13: =IF(J13=L13,"Yes","No") -> Yes | O13: =IF(E13<>L13,"Changed","Held") -> Changed | R13: Confidence | S13: Seats | T13: Correct | U13: Accuracy
A14: 10 | B14: ='AC Results'!A174 -> Thiruvottiyur | C14: ='AC Results'!Y174 -> Chennai | D14: DMK | E14: DMK+INC+VCK | F14: ='AC Results'!H174 -> 50 | G14: ='AC Results'!S174 -> DMK+INC+VCK | H14: ='AC Results'!U174 -> 4.9 | I14: ='AC Results'!V174 -> Toss-up | J14: ='AC Results'!W174 -> TVK | K14: TVK | L14: TVK | M14: =IF(G14=L14,"Yes","No") -> No | N14: =IF(J14=L14,"Yes","No") -> Yes | O14: =IF(E14<>L14,"Changed","Held") -> Changed | R14: Strong | S14: =COUNTIF($I$5:$I$238,R14) -> 69 | T14: =COUNTIFS($I$5:$I$238,R14,$M$5:$M$238,"Yes") -> 35 | U14: =IF(S14=0,"–",T14/S14) -> 0.50724638
A15: 11 | B15: ='AC Results'!A16 -> Dr. Radhakrishnan Nagar | C15: ='AC Results'!Y16 -> Chennai | D15: DMK | E15: DMK+INC+VCK | F15: ='AC Results'!H16 -> 54 | G15: ='AC Results'!S16 -> TVK | H15: ='AC Results'!U16 -> 7.8 | I15: ='AC Results'!V16 -> Lean | J15: ='AC Results'!W16 -> TVK | K15: TVK | L15: TVK | M15: =IF(G15=L15,"Yes","No") -> Yes | N15: =IF(J15=L15,"Yes","No") -> Yes | O15: =IF(E15<>L15,"Changed","Held") -> Changed | R15: Lean | S15: =COUNTIF($I$5:$I$238,R15) -> 90 | T15: =COUNTIFS($I$5:$I$238,R15,$M$5:$M$238,"Yes") -> 42 | U15: =IF(S15=0,"–",T15/S15) -> 0.46666667
A16: 12 | B16: ='AC Results'!A21 -> Perambur | C16: ='AC Results'!Y21 -> Chennai | D16: DMK | E16: DMK+INC+VCK | F16: ='AC Results'!H21 -> 95 | G16: ='AC Results'!S21 -> TVK | H16: ='AC Results'!U21 -> 31.1 | I16: ='AC Results'!V21 -> Strong | J16: ='AC Results'!W21 -> TVK | K16: TVK | L16: TVK | M16: =IF(G16=L16,"Yes","No") -> Yes | N16: =IF(J16=L16,"Yes","No") -> Yes | O16: =IF(E16<>L16,"Changed","Held") -> Changed | R16: Toss-up | S16: =COUNTIF($I$5:$I$238,R16) -> 74 | T16: =COUNTIFS($I$5:$I$238,R16,$M$5:$M$238,"Yes") -> 33 | U16: =IF(S16=0,"–",T16/S16) -> 0.44594595
A17: 13 | B17: ='AC Results'!A19 -> Kolathur | C17: ='AC Results'!Y19 -> Chennai | D17: DMK | E17: DMK+INC+VCK | F17: ='AC Results'!H19 -> 63 | G17: ='AC Results'!S19 -> TVK | H17: ='AC Results'!U19 -> 21.3 | I17: ='AC Results'!V19 -> Strong | J17: ='AC Results'!W19 -> TVK | K17: TVK | L17: TVK | M17: =IF(G17=L17,"Yes","No") -> Yes | N17: =IF(J17=L17,"Yes","No") -> Yes | O17: =IF(E17<>L17,"Changed","Held") -> Changed | R17: Low sample | S17: =COUNTIF($I$5:$I$238,R17) -> 1 | T17: =COUNTIFS($I$5:$I$238,R17,$M$5:$M$238,"Yes") -> 0 | U17: =IF(S17=0,"–",T17/S17) -> 0
A18: 14 | B18: ='AC Results'!A28 -> Villivakkam | C18: ='AC Results'!Y28 -> Chennai | D18: DMK | E18: DMK+INC+VCK | F18: ='AC Results'!H28 -> 44 | G18: ='AC Results'!S28 -> TVK | H18: ='AC Results'!U28 -> 7 | I18: ='AC Results'!V28 -> Lean | J18: ='AC Results'!W28 -> TVK | K18: TVK | L18: TVK | M18: =IF(G18=L18,"Yes","No") -> Yes | N18: =IF(J18=L18,"Yes","No") -> Yes | O18: =IF(E18<>L18,"Changed","Held") -> Changed | R18: Tie | S18: =COUNTIF($I$5:$I$238,R18) -> 0 | T18: =COUNTIFS($I$5:$I$238,R18,$M$5:$M$238,"Yes") -> 0 | U18: =IF(S18=0,"–",T18/S18) -> –
A19: 15 | B19: ='AC Results'!A24 -> Thiru-Vi-Ka-Nagar | C19: ='AC Results'!Y24 -> Chennai | D19: DMK | E19: DMK+INC+VCK | F19: ='AC Results'!H24 -> 24 | G19: ='AC Results'!S24 -> TVK | H19: ='AC Results'!U24 -> 44.8 | I19: ='AC Results'!V24 -> Lean | J19: ='AC Results'!W24 -> TVK | K19: TVK | L19: TVK | M19: =IF(G19=L19,"Yes","No") -> Yes | N19: =IF(J19=L19,"Yes","No") -> Yes | O19: =IF(E19<>L19,"Changed","Held") -> Changed
A20: 16 | B20: ='AC Results'!A17 -> Egmore | C20: ='AC Results'!Y17 -> Chennai | D20: DMK | E20: DMK+INC+VCK | F20: ='AC Results'!H17 -> 48 | G20: ='AC Results'!S17 -> DMK+INC+VCK | H20: ='AC Results'!U17 -> 11 | I20: ='AC Results'!V17 -> Strong | J20: ='AC Results'!W17 -> DMK+INC+VCK | K20: TVK | L20: TVK | M20: =IF(G20=L20,"Yes","No") -> No | N20: =IF(J20=L20,"Yes","No") -> No | O20: =IF(E20<>L20,"Changed","Held") -> Changed
A21: 17 | B21: ='AC Results'!A22 -> Royapuram | C21: ='AC Results'!Y22 -> Chennai | D21: DMK | E21: DMK+INC+VCK | F21: ='AC Results'!H22 -> 31 | G21: ='AC Results'!S22 -> DMK+INC+VCK | H21: ='AC Results'!U22 -> 2.4 | I21: ='AC Results'!V22 -> Toss-up | J21: ='AC Results'!W22 -> TVK | K21: TVK | L21: TVK | M21: =IF(G21=L21,"Yes","No") -> No | N21: =IF(J21=L21,"Yes","No") -> Yes | O21: =IF(E21<>L21,"Changed","Held") -> Changed | R21: Predicted (rows) vs actual (columns)
A22: 18 | B22: ='AC Results'!A18 -> Harbour | C22: ='AC Results'!Y18 -> Chennai | D22: DMK | E22: DMK+INC+VCK | F22: ='AC Results'!H18 -> 30 | G22: ='AC Results'!S18 -> DMK+INC+VCK | H22: ='AC Results'!U18 -> 3.7 | I22: ='AC Results'!V18 -> Toss-up | J22: ='AC Results'!W18 -> Tie | K22: DMK | L22: DMK+INC+VCK | M22: =IF(G22=L22,"Yes","No") -> Yes | N22: =IF(J22=L22,"Yes","No") -> No | O22: =IF(E22<>L22,"Changed","Held") -> Held | R22: Predicted \ Actual | S22: TVK | T22: AIADMK+ | U22: DMK+ | V22: Total | W22: Precision
A23: 19 | B23: ='AC Results'!A15 -> Chepauk-Thiruvallikeni | C23: ='AC Results'!Y15 -> Chennai | D23: DMK | E23: DMK+INC+VCK | F23: ='AC Results'!H15 -> 35 | G23: ='AC Results'!S15 -> DMK+INC+VCK | H23: ='AC Results'!U15 -> 0.3 | I23: ='AC Results'!V15 -> Toss-up | J23: ='AC Results'!W15 -> TVK | K23: DMK | L23: DMK+INC+VCK | M23: =IF(G23=L23,"Yes","No") -> Yes | N23: =IF(J23=L23,"Yes","No") -> No | O23: =IF(E23<>L23,"Changed","Held") -> Held | R23: TVK | S23: =COUNTIFS($G$5:$G$238,$R23,$L$5:$L$238,"TVK") -> 63 | T23: =COUNTIFS($G$5:$G$238,$R23,$L$5:$L$238,"AIADMK+BJP+PMK+AMMK") -> 21 | U23: =COUNTIFS($G$5:$G$238,$R23,$L$5:$L$238,"DMK+INC+VCK") -> 31 | V23: =SUM(S23:U23) -> 115 | W23: =IF(V23=0,"–",INDEX(S23:U23,MATCH($R23,{"TVK","AIADMK+BJP+PMK+AMMK","DMK+INC+VCK"},0))/V23) -> 0.54782609
A24: 20 | B24: ='AC Results'!A26 -> Thousand Lights | C24: ='AC Results'!Y26 -> Chennai | D24: DMK | E24: DMK+INC+VCK | F24: ='AC Results'!H26 -> 40 | G24: ='AC Results'!S26 -> DMK+INC+VCK | H24: ='AC Results'!U26 -> 8.9 | I24: ='AC Results'!V26 -> Lean | J24: ='AC Results'!W26 -> Tie | K24: TVK | L24: TVK | M24: =IF(G24=L24,"Yes","No") -> No | N24: =IF(J24=L24,"Yes","No") -> No | O24: =IF(E24<>L24,"Changed","Held") -> Changed | R24: AIADMK+BJP+PMK+AMMK | S24: =COUNTIFS($G$5:$G$238,$R24,$L$5:$L$238,"TVK") -> 22 | T24: =COUNTIFS($G$5:$G$238,$R24,$L$5:$L$238,"AIADMK+BJP+PMK+AMMK") -> 22 | U24: =COUNTIFS($G$5:$G$238,$R24,$L$5:$L$238,"DMK+INC+VCK") -> 16 | V24: =SUM(S24:U24) -> 60 | W24: =IF(V24=0,"–",INDEX(S24:U24,MATCH($R24,{"TVK","AIADMK+BJP+PMK+AMMK","DMK+INC+VCK"},0))/V24) -> 0.36666667
A25: 21 | B25: ='AC Results'!A14 -> Anna Nagar | C25: ='AC Results'!Y14 -> Chennai | D25: DMK | E25: DMK+INC+VCK | F25: ='AC Results'!H14 -> 49 | G25: ='AC Results'!S14 -> TVK | H25: ='AC Results'!U14 -> 9.1 | I25: ='AC Results'!V14 -> Lean | J25: ='AC Results'!W14 -> TVK | K25: TVK | L25: TVK | M25: =IF(G25=L25,"Yes","No") -> Yes | N25: =IF(J25=L25,"Yes","No") -> Yes | O25: =IF(E25<>L25,"Changed","Held") -> Changed | R25: DMK+INC+VCK | S25: =COUNTIFS($G$5:$G$238,$R25,$L$5:$L$238,"TVK") -> 22 | T25: =COUNTIFS($G$5:$G$238,$R25,$L$5:$L$238,"AIADMK+BJP+PMK+AMMK") -> 9 | U25: =COUNTIFS($G$5:$G$238,$R25,$L$5:$L$238,"DMK+INC+VCK") -> 25 | V25: =SUM(S25:U25) -> 56 | W25: =IF(V25=0,"–",INDEX(S25:U25,MATCH($R25,{"TVK","AIADMK+BJP+PMK+AMMK","DMK+INC+VCK"},0))/V25) -> 0.44642857
A26: 22 | B26: ='AC Results'!A29 -> Virugampakkam | C26: ='AC Results'!Y29 -> Chennai | D26: DMK | E26: DMK+INC+VCK | F26: ='AC Results'!H29 -> 65 | G26: ='AC Results'!S29 -> TVK | H26: ='AC Results'!U29 -> 4 | I26: ='AC Results'!V29 -> Toss-up | J26: ='AC Results'!W29 -> TVK | K26: TVK | L26: TVK | M26: =IF(G26=L26,"Yes","No") -> Yes | N26: =IF(J26=L26,"Yes","No") -> Yes | O26: =IF(E26<>L26,"Changed","Held") -> Changed | R26: NTK | S26: =COUNTIFS($G$5:$G$238,$R26,$L$5:$L$238,"TVK") -> 1 | T26: =COUNTIFS($G$5:$G$238,$R26,$L$5:$L$238,"AIADMK+BJP+PMK+AMMK") -> 1 | U26: =COUNTIFS($G$5:$G$238,$R26,$L$5:$L$238,"DMK+INC+VCK") -> 1 | V26: =SUM(S26:U26) -> 3 | W26: –
A27: 23 | B27: ='AC Results'!A23 -> Saidapet | C27: ='AC Results'!Y23 -> Chennai | D27: DMK | E27: DMK+INC+VCK | F27: ='AC Results'!H23 -> 39 | G27: ='AC Results'!S23 -> TVK | H27: ='AC Results'!U23 -> 3.9 | I27: ='AC Results'!V23 -> Toss-up | J27: ='AC Results'!W23 -> TVK | K27: TVK | L27: TVK | M27: =IF(G27=L27,"Yes","No") -> Yes | N27: =IF(J27=L27,"Yes","No") -> Yes | O27: =IF(E27<>L27,"Changed","Held") -> Changed | R27: Tie | S27: =COUNTIFS($G$5:$G$238,$R27,$L$5:$L$238,"TVK") -> 0 | T27: =COUNTIFS($G$5:$G$238,$R27,$L$5:$L$238,"AIADMK+BJP+PMK+AMMK") -> 0 | U27: =COUNTIFS($G$5:$G$238,$R27,$L$5:$L$238,"DMK+INC+VCK") -> 0 | V27: =SUM(S27:U27) -> 0 | W27: –
A28: 24 | B28: ='AC Results'!A25 -> Thiyagarayanagar | C28: ='AC Results'!Y25 -> Chennai | D28: DMK | E28: DMK+INC+VCK | F28: ='AC Results'!H25 -> 41 | G28: ='AC Results'!S25 -> AIADMK+BJP+PMK+AMMK | H28: ='AC Results'!U25 -> 42.6 | I28: ='AC Results'!V25 -> Strong | J28: ='AC Results'!W25 -> AIADMK+BJP+PMK+AMMK | K28: TVK | L28: TVK | M28: =IF(G28=L28,"Yes","No") -> No | N28: =IF(J28=L28,"Yes","No") -> No | O28: =IF(E28<>L28,"Changed","Held") -> Changed | R28: Total actual | S28: =SUM(S23:S27) -> 108 | T28: =SUM(T23:T27) -> 53 | U28: =SUM(U23:U27) -> 73 | V28: =SUM(V23:V27) -> 234
A29: 25 | B29: ='AC Results'!A20 -> Mylapore | C29: ='AC Results'!Y20 -> Chennai | D29: DMK | E29: DMK+INC+VCK | F29: ='AC Results'!H20 -> 45 | G29: ='AC Results'!S20 -> TVK | H29: ='AC Results'!U20 -> 10.4 | I29: ='AC Results'!V20 -> Strong | J29: ='AC Results'!W20 -> TVK | K29: TVK | L29: TVK | M29: =IF(G29=L29,"Yes","No") -> Yes | N29: =IF(J29=L29,"Yes","No") -> Yes | O29: =IF(E29<>L29,"Changed","Held") -> Changed | R29: Recall | S29: =IF(S28=0,0,S23/S28) -> 0.58333333 | T29: =IF(T28=0,0,T24/T28) -> 0.41509434 | U29: =IF(U28=0,0,U25/U28) -> 0.34246575
A30: 26 | B30: ='AC Results'!A27 -> Velachery | C30: ='AC Results'!Y27 -> Chennai | D30: INC | E30: DMK+INC+VCK | F30: ='AC Results'!H27 -> 60 | G30: ='AC Results'!S27 -> AIADMK+BJP+PMK+AMMK | H30: ='AC Results'!U27 -> 6.9 | I30: ='AC Results'!V27 -> Lean | J30: ='AC Results'!W27 -> AIADMK+BJP+PMK+AMMK | K30: TVK | L30: TVK | M30: =IF(G30=L30,"Yes","No") -> No | N30: =IF(J30=L30,"Yes","No") -> No | O30: =IF(E30<>L30,"Changed","Held") -> Changed
A31: 27 | B31: ='AC Results'!A11 -> Sholinganallur | C31: ='AC Results'!Y11 -> Chennai | D31: DMK | E31: DMK+INC+VCK | F31: ='AC Results'!H11 -> 108 | G31: ='AC Results'!S11 -> TVK | H31: ='AC Results'!U11 -> 5 | I31: ='AC Results'!V11 -> Lean | J31: ='AC Results'!W11 -> TVK | K31: TVK | L31: TVK | M31: =IF(G31=L31,"Yes","No") -> Yes | N31: =IF(J31=L31,"Yes","No") -> Yes | O31: =IF(E31<>L31,"Changed","Held") -> Changed
